2022-11-07 17:46:58,080 - apscheduler.scheduler - INFO - Scheduler started
2022-11-07 17:46:58,085 - telegram.ext._application - INFO - Application started
2022-11-07 17:48:45,115 - root - INFO - 910241302-aaa
2022-11-07 17:52:22,269 - root - INFO - 910241302-https://t66y.com/htm_mob/2211/7/5370230.html
2022-11-07 18:05:09,782 - root - INFO - 910241302-https://t66y.com/htm_mob/2211/7/5368433.html
2022-11-07 18:06:09,239 - root - INFO - 910241302-https://t66y.com/htm_mob/2211/7/5370589.html
2022-11-07 18:06:39,337 - root - INFO - 910241302-https://t66y.com/htm_mob/2211/7/5370894.html
2022-11-07 18:07:21,503 - root - INFO - 910241302-https://t66y.com/htm_mob/2211/7/5368190.html
2022-11-07 18:07:55,419 - root - INFO - 910241302-https://t66y.com/htm_mob/2209/7/5286482.html
2022-11-07 18:08:45,406 - root - INFO - 910241302-https://t66y.com/htm_mob/2211/7/5370973.html
2022-11-07 18:12:17,874 - root - INFO - 910241302-https://t66y.com/htm_mob/2211/7/5370409.html
2022-11-07 22:51:05,191 - telegram.ext._updater - INFO - Flood control exceeded. Retry in 5 seconds
2022-11-08 02:34:59,148 - telegram.ext._application - INFO - Application is stopping. This might take a moment.
2022-11-08 09:14:56,284 - apscheduler.scheduler - INFO - Scheduler started
2022-11-08 09:14:56,327 - telegram.ext._application - INFO - Application started
2022-11-08 09:19:11,479 - telegram.ext._application - INFO - Application is stopping. This might take a moment.
2022-11-08 09:19:11,487 - apscheduler.scheduler - INFO - Scheduler has been shut down
2022-11-08 09:19:11,497 - telegram.ext._application - INFO - Application.stop() complete
2022-11-08 09:22:15,050 - apscheduler.scheduler - INFO - Scheduler started
2022-11-08 09:22:15,054 - telegram.ext._application - INFO - Application started
2022-11-08 09:22:15,551 - root - INFO - 910241302-sss
2022-11-08 09:22:16,101 - root - INFO - 910241302-aaa
2022-11-08 09:22:16,526 - root - INFO - 910241302-aa
2022-11-08 09:26:33,350 - root - INFO - 910241302-aa
2022-11-08 09:49:57,795 - root - INFO - 910241302-https://t66y.com/htm_mob/2211/7/5371691.html
2022-11-08 09:56:07,427 - root - INFO - 910241302-https://t66y.com/htm_mob/2211/7/5371635.html
2022-11-08 10:19:59,737 - root - INFO - 910241302-https://t66y.com/htm_mob/2211/7/5369797.html
2022-11-08 10:28:48,527 - root - INFO - 910241302-https://t66y.com/htm_mob/2211/7/5371569.html
2022-11-08 10:30:08,505 - root - INFO - 910241302-https://t66y.com/htm_mob/2211/16/5335781.html
2022-11-08 10:30:43,133 - root - INFO - 910241302-https://t66y.com/htm_mob/2211/16/5330824.html
2022-11-08 10:48:23,706 - root - INFO - 910241302-https://t66y.com/htm_mob/2211/8/5372385.html
2022-11-08 10:48:54,893 - root - INFO - 910241302-https://t66y.com/htm_mob/2211/8/5372236.html
2022-11-08 10:56:05,784 - root - INFO - 910241302-https://t66y.com/htm_mob/2211/8/5372092.html
2022-11-08 11:17:58,415 - root - INFO - 910241302-https://t66y.com/htm_mob/2211/8/5371986.html
2022-11-08 11:19:26,040 - root - INFO - 910241302-https://t66y.com/htm_mob/2211/8/5371836.html
2022-11-08 11:19:44,673 - root - INFO - 910241302-https://t66y.com/htm_mob/2211/8/5371849.html
2022-11-08 11:21:43,448 - root - INFO - 910241302-https://t66y.com/htm_mob/2211/8/5371788.html
2022-11-08 11:23:07,839 - root - INFO - 910241302-https://t66y.com/htm_mob/2211/8/5371738.html
2022-11-08 11:26:12,430 - root - INFO - 910241302-https://t66y.com/htm_mob/2211/8/5371737.html
2022-11-08 11:29:29,784 - root - INFO - 910241302-https://t66y.com/htm_mob/2211/8/5371736.html
2022-11-08 11:35:17,927 - root - INFO - 910241302-https://t66y.com/htm_mob/2211/8/5371682.html
2022-11-08 11:36:01,843 - root - INFO - 910241302-https://t66y.com/htm_mob/2211/8/5371620.html
2022-11-08 11:37:24,227 - root - INFO - 910241302-https://t66y.com/htm_mob/2211/8/5371514.html
2022-11-08 11:38:39,866 - root - INFO - 910241302-https://t66y.com/htm_mob/2211/8/5371625.html
2022-11-08 11:40:19,411 - root - INFO - 910241302-https://t66y.com/htm_mob/2211/7/5371530.html
2022-11-08 11:41:23,104 - root - INFO - 910241302-https://t66y.com/htm_mob/2211/7/5372090.html
2022-11-08 11:42:52,936 - root - INFO - 910241302-https://t66y.com/htm_mob/2211/7/5370409.html
2022-11-08 11:52:27,349 - root - INFO - 910241302-https://t66y.com/htm_mob/2211/8/5372082.html
2022-11-08 11:55:29,271 - root - INFO - 910241302-https://t66y.com/htm_mob/2211/8/5362620.html
2022-11-08 11:56:19,129 - root - INFO - 910241302-https://t66y.com/htm_mob/2211/8/5364475.html
2022-11-08 11:57:32,218 - telegram.ext._updater - ERROR - Error while getting Updates: httpx HTTPError: 
2022-11-08 11:57:32,224 - telegram.ext._application - ERROR - No error handlers are registered, logging exception.
Traceback (most recent call last):
  File "/usr/lib/python3.7/asyncio/selector_events.py", line 801, in _read_ready__data_received
    data = self._sock.recv(self.max_size)
ConnectionResetError: [Errno 104] Connection reset by peer

The above exception was the direct cause of the following exception:

Traceback (most recent call last):
  File "/usr/local/lib/python3.7/dist-packages/httpcore/_exceptions.py", line 8, in map_exceptions
    yield
  File "/usr/local/lib/python3.7/dist-packages/httpcore/backends/asyncio.py", line 33, in read
    return await self._stream.receive(max_bytes=max_bytes)
  File "/usr/local/lib/python3.7/dist-packages/anyio/streams/tls.py", line 195, in receive
    data = await self._call_sslobject_method(self._ssl_object.read, max_bytes)
  File "/usr/local/lib/python3.7/dist-packages/anyio/streams/tls.py", line 137, in _call_sslobject_method
    data = await self.transport_stream.receive()
  File "/usr/local/lib/python3.7/dist-packages/anyio/_backends/_asyncio.py", line 1274, in receive
    raise self._protocol.exception
anyio.BrokenResourceError

During handling of the above exception, another exception occurred:

Traceback (most recent call last):
  File "/usr/local/lib/python3.7/dist-packages/httpx/_transports/default.py", line 60, in map_httpcore_exceptions
    yield
  File "/usr/local/lib/python3.7/dist-packages/httpx/_transports/default.py", line 353, in handle_async_request
    resp = await self._pool.handle_async_request(req)
  File "/usr/local/lib/python3.7/dist-packages/httpcore/_async/connection_pool.py", line 253, in handle_async_request
    raise exc
  File "/usr/local/lib/python3.7/dist-packages/httpcore/_async/connection_pool.py", line 237, in handle_async_request
    response = await connection.handle_async_request(request)
  File "/usr/local/lib/python3.7/dist-packages/httpcore/_async/connection.py", line 90, in handle_async_request
    return await self._connection.handle_async_request(request)
  File "/usr/local/lib/python3.7/dist-packages/httpcore/_async/http11.py", line 105, in handle_async_request
    raise exc
  File "/usr/local/lib/python3.7/dist-packages/httpcore/_async/http11.py", line 84, in handle_async_request
    ) = await self._receive_response_headers(**kwargs)
  File "/usr/local/lib/python3.7/dist-packages/httpcore/_async/http11.py", line 148, in _receive_response_headers
    event = await self._receive_event(timeout=timeout)
  File "/usr/local/lib/python3.7/dist-packages/httpcore/_async/http11.py", line 178, in _receive_event
    self.READ_NUM_BYTES, timeout=timeout
  File "/usr/local/lib/python3.7/dist-packages/httpcore/backends/asyncio.py", line 35, in read
    return b""
  File "/usr/lib/python3.7/contextlib.py", line 130, in __exit__
    self.gen.throw(type, value, traceback)
  File "/usr/local/lib/python3.7/dist-packages/httpcore/_exceptions.py", line 12, in map_exceptions
    raise to_exc(exc)
httpcore.ReadError

The above exception was the direct cause of the following exception:

Traceback (most recent call last):
  File "/usr/local/lib/python3.7/dist-packages/telegram/request/_httpxrequest.py", line 180, in do_request
    data=data,
  File "/usr/local/lib/python3.7/dist-packages/httpx/_client.py", line 1527, in request
    return await self.send(request, auth=auth, follow_redirects=follow_redirects)
  File "/usr/local/lib/python3.7/dist-packages/httpx/_client.py", line 1618, in send
    history=[],
  File "/usr/local/lib/python3.7/dist-packages/httpx/_client.py", line 1645, in _send_handling_auth
    history=history,
  File "/usr/local/lib/python3.7/dist-packages/httpx/_client.py", line 1679, in _send_handling_redirects
    response = await self._send_single_request(request)
  File "/usr/local/lib/python3.7/dist-packages/httpx/_client.py", line 1716, in _send_single_request
    response = await transport.handle_async_request(request)
  File "/usr/local/lib/python3.7/dist-packages/httpx/_transports/default.py", line 353, in handle_async_request
    resp = await self._pool.handle_async_request(req)
  File "/usr/lib/python3.7/contextlib.py", line 130, in __exit__
    self.gen.throw(type, value, traceback)
  File "/usr/local/lib/python3.7/dist-packages/httpx/_transports/default.py", line 77, in map_httpcore_exceptions
    raise mapped_exc(message) from exc
httpx.ReadError

The above exception was the direct cause of the following exception:

Traceback (most recent call last):
  File "/usr/local/lib/python3.7/dist-packages/telegram/ext/_updater.py", line 573, in _network_loop_retry
    if not await action_cb():
  File "/usr/local/lib/python3.7/dist-packages/telegram/ext/_updater.py", line 318, in polling_action_cb
    raise exc
  File "/usr/local/lib/python3.7/dist-packages/telegram/ext/_updater.py", line 310, in polling_action_cb
    allowed_updates=allowed_updates,
  File "/usr/local/lib/python3.7/dist-packages/telegram/ext/_extbot.py", line 489, in get_updates
    api_kwargs=api_kwargs,
  File "/usr/local/lib/python3.7/dist-packages/telegram/_bot.py", line 242, in decorator
    result = await func(*args, **kwargs)
  File "/usr/local/lib/python3.7/dist-packages/telegram/_bot.py", line 3899, in get_updates
    api_kwargs=api_kwargs,
  File "/usr/local/lib/python3.7/dist-packages/telegram/_bot.py", line 309, in _post
    pool_timeout=pool_timeout,
  File "/usr/local/lib/python3.7/dist-packages/telegram/ext/_extbot.py", line 287, in _do_post
    read_timeout=read_timeout,
  File "/usr/local/lib/python3.7/dist-packages/telegram/_bot.py", line 340, in _do_post
    pool_timeout=pool_timeout,
  File "/usr/local/lib/python3.7/dist-packages/telegram/request/_baserequest.py", line 169, in post
    pool_timeout=pool_timeout,
  File "/usr/local/lib/python3.7/dist-packages/telegram/request/_baserequest.py", line 285, in _request_wrapper
    raise exc
  File "/usr/local/lib/python3.7/dist-packages/telegram/request/_baserequest.py", line 278, in _request_wrapper
    pool_timeout=pool_timeout,
  File "/usr/local/lib/python3.7/dist-packages/telegram/request/_httpxrequest.py", line 195, in do_request
    raise NetworkError(f"httpx HTTPError: {err}") from err
telegram.error.NetworkError: httpx HTTPError: 
2022-11-08 12:40:05,601 - telegram.ext._updater - ERROR - Error while getting Updates: httpx HTTPError: 
2022-11-08 12:40:05,624 - telegram.ext._application - ERROR - No error handlers are registered, logging exception.
Traceback (most recent call last):
  File "/usr/lib/python3.7/asyncio/selector_events.py", line 801, in _read_ready__data_received
    data = self._sock.recv(self.max_size)
ConnectionResetError: [Errno 104] Connection reset by peer

The above exception was the direct cause of the following exception:

Traceback (most recent call last):
  File "/usr/local/lib/python3.7/dist-packages/httpcore/_exceptions.py", line 8, in map_exceptions
    yield
  File "/usr/local/lib/python3.7/dist-packages/httpcore/backends/asyncio.py", line 33, in read
    return await self._stream.receive(max_bytes=max_bytes)
  File "/usr/local/lib/python3.7/dist-packages/anyio/streams/tls.py", line 195, in receive
    data = await self._call_sslobject_method(self._ssl_object.read, max_bytes)
  File "/usr/local/lib/python3.7/dist-packages/anyio/streams/tls.py", line 137, in _call_sslobject_method
    data = await self.transport_stream.receive()
  File "/usr/local/lib/python3.7/dist-packages/anyio/_backends/_asyncio.py", line 1274, in receive
    raise self._protocol.exception
anyio.BrokenResourceError

During handling of the above exception, another exception occurred:

Traceback (most recent call last):
  File "/usr/local/lib/python3.7/dist-packages/httpx/_transports/default.py", line 60, in map_httpcore_exceptions
    yield
  File "/usr/local/lib/python3.7/dist-packages/httpx/_transports/default.py", line 353, in handle_async_request
    resp = await self._pool.handle_async_request(req)
  File "/usr/local/lib/python3.7/dist-packages/httpcore/_async/connection_pool.py", line 253, in handle_async_request
    raise exc
  File "/usr/local/lib/python3.7/dist-packages/httpcore/_async/connection_pool.py", line 237, in handle_async_request
    response = await connection.handle_async_request(request)
  File "/usr/local/lib/python3.7/dist-packages/httpcore/_async/connection.py", line 90, in handle_async_request
    return await self._connection.handle_async_request(request)
  File "/usr/local/lib/python3.7/dist-packages/httpcore/_async/http11.py", line 105, in handle_async_request
    raise exc
  File "/usr/local/lib/python3.7/dist-packages/httpcore/_async/http11.py", line 84, in handle_async_request
    ) = await self._receive_response_headers(**kwargs)
  File "/usr/local/lib/python3.7/dist-packages/httpcore/_async/http11.py", line 148, in _receive_response_headers
    event = await self._receive_event(timeout=timeout)
  File "/usr/local/lib/python3.7/dist-packages/httpcore/_async/http11.py", line 178, in _receive_event
    self.READ_NUM_BYTES, timeout=timeout
  File "/usr/local/lib/python3.7/dist-packages/httpcore/backends/asyncio.py", line 35, in read
    return b""
  File "/usr/lib/python3.7/contextlib.py", line 130, in __exit__
    self.gen.throw(type, value, traceback)
  File "/usr/local/lib/python3.7/dist-packages/httpcore/_exceptions.py", line 12, in map_exceptions
    raise to_exc(exc)
httpcore.ReadError

The above exception was the direct cause of the following exception:

Traceback (most recent call last):
  File "/usr/local/lib/python3.7/dist-packages/telegram/request/_httpxrequest.py", line 180, in do_request
    data=data,
  File "/usr/local/lib/python3.7/dist-packages/httpx/_client.py", line 1527, in request
    return await self.send(request, auth=auth, follow_redirects=follow_redirects)
  File "/usr/local/lib/python3.7/dist-packages/httpx/_client.py", line 1618, in send
    history=[],
  File "/usr/local/lib/python3.7/dist-packages/httpx/_client.py", line 1645, in _send_handling_auth
    history=history,
  File "/usr/local/lib/python3.7/dist-packages/httpx/_client.py", line 1679, in _send_handling_redirects
    response = await self._send_single_request(request)
  File "/usr/local/lib/python3.7/dist-packages/httpx/_client.py", line 1716, in _send_single_request
    response = await transport.handle_async_request(request)
  File "/usr/local/lib/python3.7/dist-packages/httpx/_transports/default.py", line 353, in handle_async_request
    resp = await self._pool.handle_async_request(req)
  File "/usr/lib/python3.7/contextlib.py", line 130, in __exit__
    self.gen.throw(type, value, traceback)
  File "/usr/local/lib/python3.7/dist-packages/httpx/_transports/default.py", line 77, in map_httpcore_exceptions
    raise mapped_exc(message) from exc
httpx.ReadError

The above exception was the direct cause of the following exception:

Traceback (most recent call last):
  File "/usr/local/lib/python3.7/dist-packages/telegram/ext/_updater.py", line 573, in _network_loop_retry
    if not await action_cb():
  File "/usr/local/lib/python3.7/dist-packages/telegram/ext/_updater.py", line 318, in polling_action_cb
    raise exc
  File "/usr/local/lib/python3.7/dist-packages/telegram/ext/_updater.py", line 310, in polling_action_cb
    allowed_updates=allowed_updates,
  File "/usr/local/lib/python3.7/dist-packages/telegram/ext/_extbot.py", line 489, in get_updates
    api_kwargs=api_kwargs,
  File "/usr/local/lib/python3.7/dist-packages/telegram/_bot.py", line 242, in decorator
    result = await func(*args, **kwargs)
  File "/usr/local/lib/python3.7/dist-packages/telegram/_bot.py", line 3899, in get_updates
    api_kwargs=api_kwargs,
  File "/usr/local/lib/python3.7/dist-packages/telegram/_bot.py", line 309, in _post
    pool_timeout=pool_timeout,
  File "/usr/local/lib/python3.7/dist-packages/telegram/ext/_extbot.py", line 287, in _do_post
    read_timeout=read_timeout,
  File "/usr/local/lib/python3.7/dist-packages/telegram/_bot.py", line 340, in _do_post
    pool_timeout=pool_timeout,
  File "/usr/local/lib/python3.7/dist-packages/telegram/request/_baserequest.py", line 169, in post
    pool_timeout=pool_timeout,
  File "/usr/local/lib/python3.7/dist-packages/telegram/request/_baserequest.py", line 285, in _request_wrapper
    raise exc
  File "/usr/local/lib/python3.7/dist-packages/telegram/request/_baserequest.py", line 278, in _request_wrapper
    pool_timeout=pool_timeout,
  File "/usr/local/lib/python3.7/dist-packages/telegram/request/_httpxrequest.py", line 195, in do_request
    raise NetworkError(f"httpx HTTPError: {err}") from err
telegram.error.NetworkError: httpx HTTPError: 
2022-11-08 12:40:27,397 - telegram.ext._updater - ERROR - Error while getting Updates: httpx HTTPError: 
2022-11-08 12:40:27,397 - telegram.ext._application - ERROR - No error handlers are registered, logging exception.
Traceback (most recent call last):
  File "/usr/lib/python3.7/asyncio/selector_events.py", line 801, in _read_ready__data_received
    data = self._sock.recv(self.max_size)
ConnectionResetError: [Errno 104] Connection reset by peer

The above exception was the direct cause of the following exception:

Traceback (most recent call last):
  File "/usr/local/lib/python3.7/dist-packages/httpcore/_exceptions.py", line 8, in map_exceptions
    yield
  File "/usr/local/lib/python3.7/dist-packages/httpcore/backends/asyncio.py", line 33, in read
    return await self._stream.receive(max_bytes=max_bytes)
  File "/usr/local/lib/python3.7/dist-packages/anyio/streams/tls.py", line 195, in receive
    data = await self._call_sslobject_method(self._ssl_object.read, max_bytes)
  File "/usr/local/lib/python3.7/dist-packages/anyio/streams/tls.py", line 137, in _call_sslobject_method
    data = await self.transport_stream.receive()
  File "/usr/local/lib/python3.7/dist-packages/anyio/_backends/_asyncio.py", line 1274, in receive
    raise self._protocol.exception
anyio.BrokenResourceError

During handling of the above exception, another exception occurred:

Traceback (most recent call last):
  File "/usr/local/lib/python3.7/dist-packages/httpx/_transports/default.py", line 60, in map_httpcore_exceptions
    yield
  File "/usr/local/lib/python3.7/dist-packages/httpx/_transports/default.py", line 353, in handle_async_request
    resp = await self._pool.handle_async_request(req)
  File "/usr/local/lib/python3.7/dist-packages/httpcore/_async/connection_pool.py", line 253, in handle_async_request
    raise exc
  File "/usr/local/lib/python3.7/dist-packages/httpcore/_async/connection_pool.py", line 237, in handle_async_request
    response = await connection.handle_async_request(request)
  File "/usr/local/lib/python3.7/dist-packages/httpcore/_async/connection.py", line 90, in handle_async_request
    return await self._connection.handle_async_request(request)
  File "/usr/local/lib/python3.7/dist-packages/httpcore/_async/http11.py", line 105, in handle_async_request
    raise exc
  File "/usr/local/lib/python3.7/dist-packages/httpcore/_async/http11.py", line 84, in handle_async_request
    ) = await self._receive_response_headers(**kwargs)
  File "/usr/local/lib/python3.7/dist-packages/httpcore/_async/http11.py", line 148, in _receive_response_headers
    event = await self._receive_event(timeout=timeout)
  File "/usr/local/lib/python3.7/dist-packages/httpcore/_async/http11.py", line 178, in _receive_event
    self.READ_NUM_BYTES, timeout=timeout
  File "/usr/local/lib/python3.7/dist-packages/httpcore/backends/asyncio.py", line 35, in read
    return b""
  File "/usr/lib/python3.7/contextlib.py", line 130, in __exit__
    self.gen.throw(type, value, traceback)
  File "/usr/local/lib/python3.7/dist-packages/httpcore/_exceptions.py", line 12, in map_exceptions
    raise to_exc(exc)
httpcore.ReadError

The above exception was the direct cause of the following exception:

Traceback (most recent call last):
  File "/usr/local/lib/python3.7/dist-packages/telegram/request/_httpxrequest.py", line 180, in do_request
    data=data,
  File "/usr/local/lib/python3.7/dist-packages/httpx/_client.py", line 1527, in request
    return await self.send(request, auth=auth, follow_redirects=follow_redirects)
  File "/usr/local/lib/python3.7/dist-packages/httpx/_client.py", line 1618, in send
    history=[],
  File "/usr/local/lib/python3.7/dist-packages/httpx/_client.py", line 1645, in _send_handling_auth
    history=history,
  File "/usr/local/lib/python3.7/dist-packages/httpx/_client.py", line 1679, in _send_handling_redirects
    response = await self._send_single_request(request)
  File "/usr/local/lib/python3.7/dist-packages/httpx/_client.py", line 1716, in _send_single_request
    response = await transport.handle_async_request(request)
  File "/usr/local/lib/python3.7/dist-packages/httpx/_transports/default.py", line 353, in handle_async_request
    resp = await self._pool.handle_async_request(req)
  File "/usr/lib/python3.7/contextlib.py", line 130, in __exit__
    self.gen.throw(type, value, traceback)
  File "/usr/local/lib/python3.7/dist-packages/httpx/_transports/default.py", line 77, in map_httpcore_exceptions
    raise mapped_exc(message) from exc
httpx.ReadError

The above exception was the direct cause of the following exception:

Traceback (most recent call last):
  File "/usr/local/lib/python3.7/dist-packages/telegram/ext/_updater.py", line 573, in _network_loop_retry
    if not await action_cb():
  File "/usr/local/lib/python3.7/dist-packages/telegram/ext/_updater.py", line 318, in polling_action_cb
    raise exc
  File "/usr/local/lib/python3.7/dist-packages/telegram/ext/_updater.py", line 310, in polling_action_cb
    allowed_updates=allowed_updates,
  File "/usr/local/lib/python3.7/dist-packages/telegram/ext/_extbot.py", line 489, in get_updates
    api_kwargs=api_kwargs,
  File "/usr/local/lib/python3.7/dist-packages/telegram/_bot.py", line 242, in decorator
    result = await func(*args, **kwargs)
  File "/usr/local/lib/python3.7/dist-packages/telegram/_bot.py", line 3899, in get_updates
    api_kwargs=api_kwargs,
  File "/usr/local/lib/python3.7/dist-packages/telegram/_bot.py", line 309, in _post
    pool_timeout=pool_timeout,
  File "/usr/local/lib/python3.7/dist-packages/telegram/ext/_extbot.py", line 287, in _do_post
    read_timeout=read_timeout,
  File "/usr/local/lib/python3.7/dist-packages/telegram/_bot.py", line 340, in _do_post
    pool_timeout=pool_timeout,
  File "/usr/local/lib/python3.7/dist-packages/telegram/request/_baserequest.py", line 169, in post
    pool_timeout=pool_timeout,
  File "/usr/local/lib/python3.7/dist-packages/telegram/request/_baserequest.py", line 285, in _request_wrapper
    raise exc
  File "/usr/local/lib/python3.7/dist-packages/telegram/request/_baserequest.py", line 278, in _request_wrapper
    pool_timeout=pool_timeout,
  File "/usr/local/lib/python3.7/dist-packages/telegram/request/_httpxrequest.py", line 195, in do_request
    raise NetworkError(f"httpx HTTPError: {err}") from err
telegram.error.NetworkError: httpx HTTPError: 
2022-11-08 13:13:51,931 - telegram.ext._updater - ERROR - Error while getting Updates: httpx HTTPError: 
2022-11-08 13:13:51,935 - telegram.ext._application - ERROR - No error handlers are registered, logging exception.
Traceback (most recent call last):
  File "/usr/lib/python3.7/asyncio/selector_events.py", line 801, in _read_ready__data_received
    data = self._sock.recv(self.max_size)
ConnectionResetError: [Errno 104] Connection reset by peer

The above exception was the direct cause of the following exception:

Traceback (most recent call last):
  File "/usr/local/lib/python3.7/dist-packages/httpcore/_exceptions.py", line 8, in map_exceptions
    yield
  File "/usr/local/lib/python3.7/dist-packages/httpcore/backends/asyncio.py", line 33, in read
    return await self._stream.receive(max_bytes=max_bytes)
  File "/usr/local/lib/python3.7/dist-packages/anyio/streams/tls.py", line 195, in receive
    data = await self._call_sslobject_method(self._ssl_object.read, max_bytes)
  File "/usr/local/lib/python3.7/dist-packages/anyio/streams/tls.py", line 137, in _call_sslobject_method
    data = await self.transport_stream.receive()
  File "/usr/local/lib/python3.7/dist-packages/anyio/_backends/_asyncio.py", line 1274, in receive
    raise self._protocol.exception
anyio.BrokenResourceError

During handling of the above exception, another exception occurred:

Traceback (most recent call last):
  File "/usr/local/lib/python3.7/dist-packages/httpx/_transports/default.py", line 60, in map_httpcore_exceptions
    yield
  File "/usr/local/lib/python3.7/dist-packages/httpx/_transports/default.py", line 353, in handle_async_request
    resp = await self._pool.handle_async_request(req)
  File "/usr/local/lib/python3.7/dist-packages/httpcore/_async/connection_pool.py", line 253, in handle_async_request
    raise exc
  File "/usr/local/lib/python3.7/dist-packages/httpcore/_async/connection_pool.py", line 237, in handle_async_request
    response = await connection.handle_async_request(request)
  File "/usr/local/lib/python3.7/dist-packages/httpcore/_async/connection.py", line 90, in handle_async_request
    return await self._connection.handle_async_request(request)
  File "/usr/local/lib/python3.7/dist-packages/httpcore/_async/http11.py", line 105, in handle_async_request
    raise exc
  File "/usr/local/lib/python3.7/dist-packages/httpcore/_async/http11.py", line 84, in handle_async_request
    ) = await self._receive_response_headers(**kwargs)
  File "/usr/local/lib/python3.7/dist-packages/httpcore/_async/http11.py", line 148, in _receive_response_headers
    event = await self._receive_event(timeout=timeout)
  File "/usr/local/lib/python3.7/dist-packages/httpcore/_async/http11.py", line 178, in _receive_event
    self.READ_NUM_BYTES, timeout=timeout
  File "/usr/local/lib/python3.7/dist-packages/httpcore/backends/asyncio.py", line 35, in read
    return b""
  File "/usr/lib/python3.7/contextlib.py", line 130, in __exit__
    self.gen.throw(type, value, traceback)
  File "/usr/local/lib/python3.7/dist-packages/httpcore/_exceptions.py", line 12, in map_exceptions
    raise to_exc(exc)
httpcore.ReadError

The above exception was the direct cause of the following exception:

Traceback (most recent call last):
  File "/usr/local/lib/python3.7/dist-packages/telegram/request/_httpxrequest.py", line 180, in do_request
    data=data,
  File "/usr/local/lib/python3.7/dist-packages/httpx/_client.py", line 1527, in request
    return await self.send(request, auth=auth, follow_redirects=follow_redirects)
  File "/usr/local/lib/python3.7/dist-packages/httpx/_client.py", line 1618, in send
    history=[],
  File "/usr/local/lib/python3.7/dist-packages/httpx/_client.py", line 1645, in _send_handling_auth
    history=history,
  File "/usr/local/lib/python3.7/dist-packages/httpx/_client.py", line 1679, in _send_handling_redirects
    response = await self._send_single_request(request)
  File "/usr/local/lib/python3.7/dist-packages/httpx/_client.py", line 1716, in _send_single_request
    response = await transport.handle_async_request(request)
  File "/usr/local/lib/python3.7/dist-packages/httpx/_transports/default.py", line 353, in handle_async_request
    resp = await self._pool.handle_async_request(req)
  File "/usr/lib/python3.7/contextlib.py", line 130, in __exit__
    self.gen.throw(type, value, traceback)
  File "/usr/local/lib/python3.7/dist-packages/httpx/_transports/default.py", line 77, in map_httpcore_exceptions
    raise mapped_exc(message) from exc
httpx.ReadError

The above exception was the direct cause of the following exception:

Traceback (most recent call last):
  File "/usr/local/lib/python3.7/dist-packages/telegram/ext/_updater.py", line 573, in _network_loop_retry
    if not await action_cb():
  File "/usr/local/lib/python3.7/dist-packages/telegram/ext/_updater.py", line 318, in polling_action_cb
    raise exc
  File "/usr/local/lib/python3.7/dist-packages/telegram/ext/_updater.py", line 310, in polling_action_cb
    allowed_updates=allowed_updates,
  File "/usr/local/lib/python3.7/dist-packages/telegram/ext/_extbot.py", line 489, in get_updates
    api_kwargs=api_kwargs,
  File "/usr/local/lib/python3.7/dist-packages/telegram/_bot.py", line 242, in decorator
    result = await func(*args, **kwargs)
  File "/usr/local/lib/python3.7/dist-packages/telegram/_bot.py", line 3899, in get_updates
    api_kwargs=api_kwargs,
  File "/usr/local/lib/python3.7/dist-packages/telegram/_bot.py", line 309, in _post
    pool_timeout=pool_timeout,
  File "/usr/local/lib/python3.7/dist-packages/telegram/ext/_extbot.py", line 287, in _do_post
    read_timeout=read_timeout,
  File "/usr/local/lib/python3.7/dist-packages/telegram/_bot.py", line 340, in _do_post
    pool_timeout=pool_timeout,
  File "/usr/local/lib/python3.7/dist-packages/telegram/request/_baserequest.py", line 169, in post
    pool_timeout=pool_timeout,
  File "/usr/local/lib/python3.7/dist-packages/telegram/request/_baserequest.py", line 285, in _request_wrapper
    raise exc
  File "/usr/local/lib/python3.7/dist-packages/telegram/request/_baserequest.py", line 278, in _request_wrapper
    pool_timeout=pool_timeout,
  File "/usr/local/lib/python3.7/dist-packages/telegram/request/_httpxrequest.py", line 195, in do_request
    raise NetworkError(f"httpx HTTPError: {err}") from err
telegram.error.NetworkError: httpx HTTPError: 
2022-11-08 13:14:13,806 - telegram.ext._updater - ERROR - Error while getting Updates: httpx HTTPError: 
2022-11-08 13:14:13,807 - telegram.ext._application - ERROR - No error handlers are registered, logging exception.
Traceback (most recent call last):
  File "/usr/lib/python3.7/asyncio/selector_events.py", line 801, in _read_ready__data_received
    data = self._sock.recv(self.max_size)
ConnectionResetError: [Errno 104] Connection reset by peer

The above exception was the direct cause of the following exception:

Traceback (most recent call last):
  File "/usr/local/lib/python3.7/dist-packages/httpcore/_exceptions.py", line 8, in map_exceptions
    yield
  File "/usr/local/lib/python3.7/dist-packages/httpcore/backends/asyncio.py", line 33, in read
    return await self._stream.receive(max_bytes=max_bytes)
  File "/usr/local/lib/python3.7/dist-packages/anyio/streams/tls.py", line 195, in receive
    data = await self._call_sslobject_method(self._ssl_object.read, max_bytes)
  File "/usr/local/lib/python3.7/dist-packages/anyio/streams/tls.py", line 137, in _call_sslobject_method
    data = await self.transport_stream.receive()
  File "/usr/local/lib/python3.7/dist-packages/anyio/_backends/_asyncio.py", line 1274, in receive
    raise self._protocol.exception
anyio.BrokenResourceError

During handling of the above exception, another exception occurred:

Traceback (most recent call last):
  File "/usr/local/lib/python3.7/dist-packages/httpx/_transports/default.py", line 60, in map_httpcore_exceptions
    yield
  File "/usr/local/lib/python3.7/dist-packages/httpx/_transports/default.py", line 353, in handle_async_request
    resp = await self._pool.handle_async_request(req)
  File "/usr/local/lib/python3.7/dist-packages/httpcore/_async/connection_pool.py", line 253, in handle_async_request
    raise exc
  File "/usr/local/lib/python3.7/dist-packages/httpcore/_async/connection_pool.py", line 237, in handle_async_request
    response = await connection.handle_async_request(request)
  File "/usr/local/lib/python3.7/dist-packages/httpcore/_async/connection.py", line 90, in handle_async_request
    return await self._connection.handle_async_request(request)
  File "/usr/local/lib/python3.7/dist-packages/httpcore/_async/http11.py", line 105, in handle_async_request
    raise exc
  File "/usr/local/lib/python3.7/dist-packages/httpcore/_async/http11.py", line 84, in handle_async_request
    ) = await self._receive_response_headers(**kwargs)
  File "/usr/local/lib/python3.7/dist-packages/httpcore/_async/http11.py", line 148, in _receive_response_headers
    event = await self._receive_event(timeout=timeout)
  File "/usr/local/lib/python3.7/dist-packages/httpcore/_async/http11.py", line 178, in _receive_event
    self.READ_NUM_BYTES, timeout=timeout
  File "/usr/local/lib/python3.7/dist-packages/httpcore/backends/asyncio.py", line 35, in read
    return b""
  File "/usr/lib/python3.7/contextlib.py", line 130, in __exit__
    self.gen.throw(type, value, traceback)
  File "/usr/local/lib/python3.7/dist-packages/httpcore/_exceptions.py", line 12, in map_exceptions
    raise to_exc(exc)
httpcore.ReadError

The above exception was the direct cause of the following exception:

Traceback (most recent call last):
  File "/usr/local/lib/python3.7/dist-packages/telegram/request/_httpxrequest.py", line 180, in do_request
    data=data,
  File "/usr/local/lib/python3.7/dist-packages/httpx/_client.py", line 1527, in request
    return await self.send(request, auth=auth, follow_redirects=follow_redirects)
  File "/usr/local/lib/python3.7/dist-packages/httpx/_client.py", line 1618, in send
    history=[],
  File "/usr/local/lib/python3.7/dist-packages/httpx/_client.py", line 1645, in _send_handling_auth
    history=history,
  File "/usr/local/lib/python3.7/dist-packages/httpx/_client.py", line 1679, in _send_handling_redirects
    response = await self._send_single_request(request)
  File "/usr/local/lib/python3.7/dist-packages/httpx/_client.py", line 1716, in _send_single_request
    response = await transport.handle_async_request(request)
  File "/usr/local/lib/python3.7/dist-packages/httpx/_transports/default.py", line 353, in handle_async_request
    resp = await self._pool.handle_async_request(req)
  File "/usr/lib/python3.7/contextlib.py", line 130, in __exit__
    self.gen.throw(type, value, traceback)
  File "/usr/local/lib/python3.7/dist-packages/httpx/_transports/default.py", line 77, in map_httpcore_exceptions
    raise mapped_exc(message) from exc
httpx.ReadError

The above exception was the direct cause of the following exception:

Traceback (most recent call last):
  File "/usr/local/lib/python3.7/dist-packages/telegram/ext/_updater.py", line 573, in _network_loop_retry
    if not await action_cb():
  File "/usr/local/lib/python3.7/dist-packages/telegram/ext/_updater.py", line 318, in polling_action_cb
    raise exc
  File "/usr/local/lib/python3.7/dist-packages/telegram/ext/_updater.py", line 310, in polling_action_cb
    allowed_updates=allowed_updates,
  File "/usr/local/lib/python3.7/dist-packages/telegram/ext/_extbot.py", line 489, in get_updates
    api_kwargs=api_kwargs,
  File "/usr/local/lib/python3.7/dist-packages/telegram/_bot.py", line 242, in decorator
    result = await func(*args, **kwargs)
  File "/usr/local/lib/python3.7/dist-packages/telegram/_bot.py", line 3899, in get_updates
    api_kwargs=api_kwargs,
  File "/usr/local/lib/python3.7/dist-packages/telegram/_bot.py", line 309, in _post
    pool_timeout=pool_timeout,
  File "/usr/local/lib/python3.7/dist-packages/telegram/ext/_extbot.py", line 287, in _do_post
    read_timeout=read_timeout,
  File "/usr/local/lib/python3.7/dist-packages/telegram/_bot.py", line 340, in _do_post
    pool_timeout=pool_timeout,
  File "/usr/local/lib/python3.7/dist-packages/telegram/request/_baserequest.py", line 169, in post
    pool_timeout=pool_timeout,
  File "/usr/local/lib/python3.7/dist-packages/telegram/request/_baserequest.py", line 285, in _request_wrapper
    raise exc
  File "/usr/local/lib/python3.7/dist-packages/telegram/request/_baserequest.py", line 278, in _request_wrapper
    pool_timeout=pool_timeout,
  File "/usr/local/lib/python3.7/dist-packages/telegram/request/_httpxrequest.py", line 195, in do_request
    raise NetworkError(f"httpx HTTPError: {err}") from err
telegram.error.NetworkError: httpx HTTPError: 
2022-11-08 13:14:35,629 - telegram.ext._updater - ERROR - Error while getting Updates: httpx HTTPError: 
2022-11-08 13:14:35,638 - telegram.ext._application - ERROR - No error handlers are registered, logging exception.
Traceback (most recent call last):
  File "/usr/lib/python3.7/asyncio/selector_events.py", line 801, in _read_ready__data_received
    data = self._sock.recv(self.max_size)
ConnectionResetError: [Errno 104] Connection reset by peer

The above exception was the direct cause of the following exception:

Traceback (most recent call last):
  File "/usr/local/lib/python3.7/dist-packages/httpcore/_exceptions.py", line 8, in map_exceptions
    yield
  File "/usr/local/lib/python3.7/dist-packages/httpcore/backends/asyncio.py", line 33, in read
    return await self._stream.receive(max_bytes=max_bytes)
  File "/usr/local/lib/python3.7/dist-packages/anyio/streams/tls.py", line 195, in receive
    data = await self._call_sslobject_method(self._ssl_object.read, max_bytes)
  File "/usr/local/lib/python3.7/dist-packages/anyio/streams/tls.py", line 137, in _call_sslobject_method
    data = await self.transport_stream.receive()
  File "/usr/local/lib/python3.7/dist-packages/anyio/_backends/_asyncio.py", line 1274, in receive
    raise self._protocol.exception
anyio.BrokenResourceError

During handling of the above exception, another exception occurred:

Traceback (most recent call last):
  File "/usr/local/lib/python3.7/dist-packages/httpx/_transports/default.py", line 60, in map_httpcore_exceptions
    yield
  File "/usr/local/lib/python3.7/dist-packages/httpx/_transports/default.py", line 353, in handle_async_request
    resp = await self._pool.handle_async_request(req)
  File "/usr/local/lib/python3.7/dist-packages/httpcore/_async/connection_pool.py", line 253, in handle_async_request
    raise exc
  File "/usr/local/lib/python3.7/dist-packages/httpcore/_async/connection_pool.py", line 237, in handle_async_request
    response = await connection.handle_async_request(request)
  File "/usr/local/lib/python3.7/dist-packages/httpcore/_async/connection.py", line 90, in handle_async_request
    return await self._connection.handle_async_request(request)
  File "/usr/local/lib/python3.7/dist-packages/httpcore/_async/http11.py", line 105, in handle_async_request
    raise exc
  File "/usr/local/lib/python3.7/dist-packages/httpcore/_async/http11.py", line 84, in handle_async_request
    ) = await self._receive_response_headers(**kwargs)
  File "/usr/local/lib/python3.7/dist-packages/httpcore/_async/http11.py", line 148, in _receive_response_headers
    event = await self._receive_event(timeout=timeout)
  File "/usr/local/lib/python3.7/dist-packages/httpcore/_async/http11.py", line 178, in _receive_event
    self.READ_NUM_BYTES, timeout=timeout
  File "/usr/local/lib/python3.7/dist-packages/httpcore/backends/asyncio.py", line 35, in read
    return b""
  File "/usr/lib/python3.7/contextlib.py", line 130, in __exit__
    self.gen.throw(type, value, traceback)
  File "/usr/local/lib/python3.7/dist-packages/httpcore/_exceptions.py", line 12, in map_exceptions
    raise to_exc(exc)
httpcore.ReadError

The above exception was the direct cause of the following exception:

Traceback (most recent call last):
  File "/usr/local/lib/python3.7/dist-packages/telegram/request/_httpxrequest.py", line 180, in do_request
    data=data,
  File "/usr/local/lib/python3.7/dist-packages/httpx/_client.py", line 1527, in request
    return await self.send(request, auth=auth, follow_redirects=follow_redirects)
  File "/usr/local/lib/python3.7/dist-packages/httpx/_client.py", line 1618, in send
    history=[],
  File "/usr/local/lib/python3.7/dist-packages/httpx/_client.py", line 1645, in _send_handling_auth
    history=history,
  File "/usr/local/lib/python3.7/dist-packages/httpx/_client.py", line 1679, in _send_handling_redirects
    response = await self._send_single_request(request)
  File "/usr/local/lib/python3.7/dist-packages/httpx/_client.py", line 1716, in _send_single_request
    response = await transport.handle_async_request(request)
  File "/usr/local/lib/python3.7/dist-packages/httpx/_transports/default.py", line 353, in handle_async_request
    resp = await self._pool.handle_async_request(req)
  File "/usr/lib/python3.7/contextlib.py", line 130, in __exit__
    self.gen.throw(type, value, traceback)
  File "/usr/local/lib/python3.7/dist-packages/httpx/_transports/default.py", line 77, in map_httpcore_exceptions
    raise mapped_exc(message) from exc
httpx.ReadError

The above exception was the direct cause of the following exception:

Traceback (most recent call last):
  File "/usr/local/lib/python3.7/dist-packages/telegram/ext/_updater.py", line 573, in _network_loop_retry
    if not await action_cb():
  File "/usr/local/lib/python3.7/dist-packages/telegram/ext/_updater.py", line 318, in polling_action_cb
    raise exc
  File "/usr/local/lib/python3.7/dist-packages/telegram/ext/_updater.py", line 310, in polling_action_cb
    allowed_updates=allowed_updates,
  File "/usr/local/lib/python3.7/dist-packages/telegram/ext/_extbot.py", line 489, in get_updates
    api_kwargs=api_kwargs,
  File "/usr/local/lib/python3.7/dist-packages/telegram/_bot.py", line 242, in decorator
    result = await func(*args, **kwargs)
  File "/usr/local/lib/python3.7/dist-packages/telegram/_bot.py", line 3899, in get_updates
    api_kwargs=api_kwargs,
  File "/usr/local/lib/python3.7/dist-packages/telegram/_bot.py", line 309, in _post
    pool_timeout=pool_timeout,
  File "/usr/local/lib/python3.7/dist-packages/telegram/ext/_extbot.py", line 287, in _do_post
    read_timeout=read_timeout,
  File "/usr/local/lib/python3.7/dist-packages/telegram/_bot.py", line 340, in _do_post
    pool_timeout=pool_timeout,
  File "/usr/local/lib/python3.7/dist-packages/telegram/request/_baserequest.py", line 169, in post
    pool_timeout=pool_timeout,
  File "/usr/local/lib/python3.7/dist-packages/telegram/request/_baserequest.py", line 285, in _request_wrapper
    raise exc
  File "/usr/local/lib/python3.7/dist-packages/telegram/request/_baserequest.py", line 278, in _request_wrapper
    pool_timeout=pool_timeout,
  File "/usr/local/lib/python3.7/dist-packages/telegram/request/_httpxrequest.py", line 195, in do_request
    raise NetworkError(f"httpx HTTPError: {err}") from err
telegram.error.NetworkError: httpx HTTPError: 
2022-11-08 16:06:59,920 - telegram.ext._updater - ERROR - Error while getting Updates: httpx HTTPError: 
2022-11-08 16:07:00,186 - telegram.ext._application - ERROR - No error handlers are registered, logging exception.
Traceback (most recent call last):
  File "/usr/lib/python3.7/asyncio/selector_events.py", line 801, in _read_ready__data_received
    data = self._sock.recv(self.max_size)
ConnectionResetError: [Errno 104] Connection reset by peer

The above exception was the direct cause of the following exception:

Traceback (most recent call last):
  File "/usr/local/lib/python3.7/dist-packages/httpcore/_exceptions.py", line 8, in map_exceptions
    yield
  File "/usr/local/lib/python3.7/dist-packages/httpcore/backends/asyncio.py", line 33, in read
    return await self._stream.receive(max_bytes=max_bytes)
  File "/usr/local/lib/python3.7/dist-packages/anyio/streams/tls.py", line 195, in receive
    data = await self._call_sslobject_method(self._ssl_object.read, max_bytes)
  File "/usr/local/lib/python3.7/dist-packages/anyio/streams/tls.py", line 137, in _call_sslobject_method
    data = await self.transport_stream.receive()
  File "/usr/local/lib/python3.7/dist-packages/anyio/_backends/_asyncio.py", line 1274, in receive
    raise self._protocol.exception
anyio.BrokenResourceError

During handling of the above exception, another exception occurred:

Traceback (most recent call last):
  File "/usr/local/lib/python3.7/dist-packages/httpx/_transports/default.py", line 60, in map_httpcore_exceptions
    yield
  File "/usr/local/lib/python3.7/dist-packages/httpx/_transports/default.py", line 353, in handle_async_request
    resp = await self._pool.handle_async_request(req)
  File "/usr/local/lib/python3.7/dist-packages/httpcore/_async/connection_pool.py", line 253, in handle_async_request
    raise exc
  File "/usr/local/lib/python3.7/dist-packages/httpcore/_async/connection_pool.py", line 237, in handle_async_request
    response = await connection.handle_async_request(request)
  File "/usr/local/lib/python3.7/dist-packages/httpcore/_async/connection.py", line 90, in handle_async_request
    return await self._connection.handle_async_request(request)
  File "/usr/local/lib/python3.7/dist-packages/httpcore/_async/http11.py", line 105, in handle_async_request
    raise exc
  File "/usr/local/lib/python3.7/dist-packages/httpcore/_async/http11.py", line 84, in handle_async_request
    ) = await self._receive_response_headers(**kwargs)
  File "/usr/local/lib/python3.7/dist-packages/httpcore/_async/http11.py", line 148, in _receive_response_headers
    event = await self._receive_event(timeout=timeout)
  File "/usr/local/lib/python3.7/dist-packages/httpcore/_async/http11.py", line 178, in _receive_event
    self.READ_NUM_BYTES, timeout=timeout
  File "/usr/local/lib/python3.7/dist-packages/httpcore/backends/asyncio.py", line 35, in read
    return b""
  File "/usr/lib/python3.7/contextlib.py", line 130, in __exit__
    self.gen.throw(type, value, traceback)
  File "/usr/local/lib/python3.7/dist-packages/httpcore/_exceptions.py", line 12, in map_exceptions
    raise to_exc(exc)
httpcore.ReadError

The above exception was the direct cause of the following exception:

Traceback (most recent call last):
  File "/usr/local/lib/python3.7/dist-packages/telegram/request/_httpxrequest.py", line 180, in do_request
    data=data,
  File "/usr/local/lib/python3.7/dist-packages/httpx/_client.py", line 1527, in request
    return await self.send(request, auth=auth, follow_redirects=follow_redirects)
  File "/usr/local/lib/python3.7/dist-packages/httpx/_client.py", line 1618, in send
    history=[],
  File "/usr/local/lib/python3.7/dist-packages/httpx/_client.py", line 1645, in _send_handling_auth
    history=history,
  File "/usr/local/lib/python3.7/dist-packages/httpx/_client.py", line 1679, in _send_handling_redirects
    response = await self._send_single_request(request)
  File "/usr/local/lib/python3.7/dist-packages/httpx/_client.py", line 1716, in _send_single_request
    response = await transport.handle_async_request(request)
  File "/usr/local/lib/python3.7/dist-packages/httpx/_transports/default.py", line 353, in handle_async_request
    resp = await self._pool.handle_async_request(req)
  File "/usr/lib/python3.7/contextlib.py", line 130, in __exit__
    self.gen.throw(type, value, traceback)
  File "/usr/local/lib/python3.7/dist-packages/httpx/_transports/default.py", line 77, in map_httpcore_exceptions
    raise mapped_exc(message) from exc
httpx.ReadError

The above exception was the direct cause of the following exception:

Traceback (most recent call last):
  File "/usr/local/lib/python3.7/dist-packages/telegram/ext/_updater.py", line 573, in _network_loop_retry
    if not await action_cb():
  File "/usr/local/lib/python3.7/dist-packages/telegram/ext/_updater.py", line 318, in polling_action_cb
    raise exc
  File "/usr/local/lib/python3.7/dist-packages/telegram/ext/_updater.py", line 310, in polling_action_cb
    allowed_updates=allowed_updates,
  File "/usr/local/lib/python3.7/dist-packages/telegram/ext/_extbot.py", line 489, in get_updates
    api_kwargs=api_kwargs,
  File "/usr/local/lib/python3.7/dist-packages/telegram/_bot.py", line 242, in decorator
    result = await func(*args, **kwargs)
  File "/usr/local/lib/python3.7/dist-packages/telegram/_bot.py", line 3899, in get_updates
    api_kwargs=api_kwargs,
  File "/usr/local/lib/python3.7/dist-packages/telegram/_bot.py", line 309, in _post
    pool_timeout=pool_timeout,
  File "/usr/local/lib/python3.7/dist-packages/telegram/ext/_extbot.py", line 287, in _do_post
    read_timeout=read_timeout,
  File "/usr/local/lib/python3.7/dist-packages/telegram/_bot.py", line 340, in _do_post
    pool_timeout=pool_timeout,
  File "/usr/local/lib/python3.7/dist-packages/telegram/request/_baserequest.py", line 169, in post
    pool_timeout=pool_timeout,
  File "/usr/local/lib/python3.7/dist-packages/telegram/request/_baserequest.py", line 285, in _request_wrapper
    raise exc
  File "/usr/local/lib/python3.7/dist-packages/telegram/request/_baserequest.py", line 278, in _request_wrapper
    pool_timeout=pool_timeout,
  File "/usr/local/lib/python3.7/dist-packages/telegram/request/_httpxrequest.py", line 195, in do_request
    raise NetworkError(f"httpx HTTPError: {err}") from err
telegram.error.NetworkError: httpx HTTPError: 
2022-11-08 17:25:27,709 - root - INFO - 1905615710-https://t66y.com/htm_mob/2210/7/5320042.html
2022-11-08 17:34:51,837 - root - INFO - 1905615710-https://t66y.com/htm_mob/2211/7/5371785.html
2022-11-08 17:42:16,479 - root - INFO - 1905615710-https://t66y.com/htm_mob/2211/8/5372873.html
2022-11-08 17:47:57,140 - root - INFO - 1905615710-https://t66y.com/htm_mob/2210/8/5358395.html
2022-11-09 00:58:04,332 - root - INFO - 1905615710-https://t66y.com/htm_mob/2210/7/5353805.html
2022-11-09 00:58:53,196 - root - INFO - 1905615710-https://t66y.com/htm_mob/2211/7/5373375.html
2022-11-09 01:33:26,497 - root - INFO - 1905615710-https://t66y.com/htm_mob/2203/7/4952132.html
2022-11-09 01:35:14,583 - root - INFO - 1905615710-https://t66y.com/htm_mob/2211/7/5373563.html
2022-11-09 01:41:06,576 - root - INFO - 1905615710-https://t66y.com/htm_mob/2211/7/5373553.html
2022-11-09 01:42:06,609 - root - INFO - 1905615710-https://t66y.com/htm_mob/2211/7/5371569.html
2022-11-09 01:50:02,936 - root - INFO - 1905615710-https://t66y.com/htm_mob/2211/8/5373540.html
2022-11-09 04:01:23,546 - root - INFO - 910241302-https://t66y.com/htm_data/2210/7/5352658.html
2022-11-09 09:01:42,929 - root - INFO - 910241302-https://cl.2718x.xyz/htm_mob/2211/16/5366694.html
2022-11-09 13:34:40,025 - telegram.ext._updater - ERROR - Error while getting Updates: httpx HTTPError: 
2022-11-09 13:34:40,075 - telegram.ext._application - ERROR - No error handlers are registered, logging exception.
Traceback (most recent call last):
  File "/usr/lib/python3.7/asyncio/selector_events.py", line 801, in _read_ready__data_received
    data = self._sock.recv(self.max_size)
ConnectionResetError: [Errno 104] Connection reset by peer

The above exception was the direct cause of the following exception:

Traceback (most recent call last):
  File "/usr/local/lib/python3.7/dist-packages/httpcore/_exceptions.py", line 8, in map_exceptions
    yield
  File "/usr/local/lib/python3.7/dist-packages/httpcore/backends/asyncio.py", line 33, in read
    return await self._stream.receive(max_bytes=max_bytes)
  File "/usr/local/lib/python3.7/dist-packages/anyio/streams/tls.py", line 195, in receive
    data = await self._call_sslobject_method(self._ssl_object.read, max_bytes)
  File "/usr/local/lib/python3.7/dist-packages/anyio/streams/tls.py", line 137, in _call_sslobject_method
    data = await self.transport_stream.receive()
  File "/usr/local/lib/python3.7/dist-packages/anyio/_backends/_asyncio.py", line 1274, in receive
    raise self._protocol.exception
anyio.BrokenResourceError

During handling of the above exception, another exception occurred:

Traceback (most recent call last):
  File "/usr/local/lib/python3.7/dist-packages/httpx/_transports/default.py", line 60, in map_httpcore_exceptions
    yield
  File "/usr/local/lib/python3.7/dist-packages/httpx/_transports/default.py", line 353, in handle_async_request
    resp = await self._pool.handle_async_request(req)
  File "/usr/local/lib/python3.7/dist-packages/httpcore/_async/connection_pool.py", line 253, in handle_async_request
    raise exc
  File "/usr/local/lib/python3.7/dist-packages/httpcore/_async/connection_pool.py", line 237, in handle_async_request
    response = await connection.handle_async_request(request)
  File "/usr/local/lib/python3.7/dist-packages/httpcore/_async/connection.py", line 90, in handle_async_request
    return await self._connection.handle_async_request(request)
  File "/usr/local/lib/python3.7/dist-packages/httpcore/_async/http11.py", line 105, in handle_async_request
    raise exc
  File "/usr/local/lib/python3.7/dist-packages/httpcore/_async/http11.py", line 84, in handle_async_request
    ) = await self._receive_response_headers(**kwargs)
  File "/usr/local/lib/python3.7/dist-packages/httpcore/_async/http11.py", line 148, in _receive_response_headers
    event = await self._receive_event(timeout=timeout)
  File "/usr/local/lib/python3.7/dist-packages/httpcore/_async/http11.py", line 178, in _receive_event
    self.READ_NUM_BYTES, timeout=timeout
  File "/usr/local/lib/python3.7/dist-packages/httpcore/backends/asyncio.py", line 35, in read
    return b""
  File "/usr/lib/python3.7/contextlib.py", line 130, in __exit__
    self.gen.throw(type, value, traceback)
  File "/usr/local/lib/python3.7/dist-packages/httpcore/_exceptions.py", line 12, in map_exceptions
    raise to_exc(exc)
httpcore.ReadError

The above exception was the direct cause of the following exception:

Traceback (most recent call last):
  File "/usr/local/lib/python3.7/dist-packages/telegram/request/_httpxrequest.py", line 180, in do_request
    data=data,
  File "/usr/local/lib/python3.7/dist-packages/httpx/_client.py", line 1527, in request
    return await self.send(request, auth=auth, follow_redirects=follow_redirects)
  File "/usr/local/lib/python3.7/dist-packages/httpx/_client.py", line 1618, in send
    history=[],
  File "/usr/local/lib/python3.7/dist-packages/httpx/_client.py", line 1645, in _send_handling_auth
    history=history,
  File "/usr/local/lib/python3.7/dist-packages/httpx/_client.py", line 1679, in _send_handling_redirects
    response = await self._send_single_request(request)
  File "/usr/local/lib/python3.7/dist-packages/httpx/_client.py", line 1716, in _send_single_request
    response = await transport.handle_async_request(request)
  File "/usr/local/lib/python3.7/dist-packages/httpx/_transports/default.py", line 353, in handle_async_request
    resp = await self._pool.handle_async_request(req)
  File "/usr/lib/python3.7/contextlib.py", line 130, in __exit__
    self.gen.throw(type, value, traceback)
  File "/usr/local/lib/python3.7/dist-packages/httpx/_transports/default.py", line 77, in map_httpcore_exceptions
    raise mapped_exc(message) from exc
httpx.ReadError

The above exception was the direct cause of the following exception:

Traceback (most recent call last):
  File "/usr/local/lib/python3.7/dist-packages/telegram/ext/_updater.py", line 573, in _network_loop_retry
    if not await action_cb():
  File "/usr/local/lib/python3.7/dist-packages/telegram/ext/_updater.py", line 318, in polling_action_cb
    raise exc
  File "/usr/local/lib/python3.7/dist-packages/telegram/ext/_updater.py", line 310, in polling_action_cb
    allowed_updates=allowed_updates,
  File "/usr/local/lib/python3.7/dist-packages/telegram/ext/_extbot.py", line 489, in get_updates
    api_kwargs=api_kwargs,
  File "/usr/local/lib/python3.7/dist-packages/telegram/_bot.py", line 242, in decorator
    result = await func(*args, **kwargs)
  File "/usr/local/lib/python3.7/dist-packages/telegram/_bot.py", line 3899, in get_updates
    api_kwargs=api_kwargs,
  File "/usr/local/lib/python3.7/dist-packages/telegram/_bot.py", line 309, in _post
    pool_timeout=pool_timeout,
  File "/usr/local/lib/python3.7/dist-packages/telegram/ext/_extbot.py", line 287, in _do_post
    read_timeout=read_timeout,
  File "/usr/local/lib/python3.7/dist-packages/telegram/_bot.py", line 340, in _do_post
    pool_timeout=pool_timeout,
  File "/usr/local/lib/python3.7/dist-packages/telegram/request/_baserequest.py", line 169, in post
    pool_timeout=pool_timeout,
  File "/usr/local/lib/python3.7/dist-packages/telegram/request/_baserequest.py", line 285, in _request_wrapper
    raise exc
  File "/usr/local/lib/python3.7/dist-packages/telegram/request/_baserequest.py", line 278, in _request_wrapper
    pool_timeout=pool_timeout,
  File "/usr/local/lib/python3.7/dist-packages/telegram/request/_httpxrequest.py", line 195, in do_request
    raise NetworkError(f"httpx HTTPError: {err}") from err
telegram.error.NetworkError: httpx HTTPError: 
                                                                                                                                                                                                                                                                                               2022-11-09 15:08:44,390 - apscheduler.scheduler - INFO - Scheduler started
2022-11-09 15:08:44,569 - telegram.ext._application - INFO - Application started
2022-11-09 15:13:19,912 - root - INFO - 910241302-d d
2022-11-09 15:18:24,157 - root - INFO - 910241302-ff
2022-11-09 15:25:52,356 - root - INFO - 1905615710-https://t66y.com/htm_mob/2211/7/5374690.html
2022-11-09 15:30:49,953 - root - INFO - 1905615710-https://t66y.com/htm_mob/2211/7/5373800.html
2022-11-09 15:32:04,667 - root - INFO - 1905615710-https://t66y.com/htm_mob/2211/7/5373947.html
2022-11-09 15:45:26,097 - root - INFO - 1905615710-https://t66y.com/htm_mob/2209/8/5274464.html
2022-11-09 15:48:23,068 - root - INFO - 1905615710-https://t66y.com/htm_mob/2209/8/5274356.html
2022-11-09 15:50:08,841 - root - INFO - 1905615710-https://t66y.com/htm_mob/2209/8/5273490.html
2022-11-09 16:02:57,214 - root - INFO - 1905615710-https://t66y.com/htm_mob/2210/7/5305719.html
2022-11-09 16:15:11,216 - root - INFO - 1905615710-https://t66y.com/htm_mob/2208/7/5248272.html
2022-11-10 04:27:34,506 - root - INFO - 1905615710-https://t66y.com/htm_mob/2211/7/5374794.html
2022-11-10 04:38:18,332 - root - INFO - 1905615710-https://t66y.com/htm_mob/2211/7/5375483.html
2022-11-10 09:46:13,688 - root - INFO - 910241302-https://t66y.com/htm_mob/2211/7/5374899.html
2022-11-10 09:53:31,831 - root - INFO - 910241302-https://t66y.com/htm_mob/2211/7/5376052.html
2022-11-10 10:19:32,281 - root - INFO - 910241302-https://t66y.com/htm_mob/2211/7/5374013.html
2022-11-10 12:28:05,506 - telegram.ext._updater - ERROR - Error while getting Updates: httpx HTTPError: 
2022-11-10 12:28:05,527 - telegram.ext._application - ERROR - No error handlers are registered, logging exception.
Traceback (most recent call last):
  File "/usr/lib/python3.7/asyncio/selector_events.py", line 801, in _read_ready__data_received
    data = self._sock.recv(self.max_size)
ConnectionResetError: [Errno 104] Connection reset by peer

The above exception was the direct cause of the following exception:

Traceback (most recent call last):
  File "/usr/local/lib/python3.7/dist-packages/httpcore/_exceptions.py", line 8, in map_exceptions
    yield
  File "/usr/local/lib/python3.7/dist-packages/httpcore/backends/asyncio.py", line 33, in read
    return await self._stream.receive(max_bytes=max_bytes)
  File "/usr/local/lib/python3.7/dist-packages/anyio/streams/tls.py", line 195, in receive
    data = await self._call_sslobject_method(self._ssl_object.read, max_bytes)
  File "/usr/local/lib/python3.7/dist-packages/anyio/streams/tls.py", line 137, in _call_sslobject_method
    data = await self.transport_stream.receive()
  File "/usr/local/lib/python3.7/dist-packages/anyio/_backends/_asyncio.py", line 1274, in receive
    raise self._protocol.exception
anyio.BrokenResourceError

During handling of the above exception, another exception occurred:

Traceback (most recent call last):
  File "/usr/local/lib/python3.7/dist-packages/httpx/_transports/default.py", line 60, in map_httpcore_exceptions
    yield
  File "/usr/local/lib/python3.7/dist-packages/httpx/_transports/default.py", line 353, in handle_async_request
    resp = await self._pool.handle_async_request(req)
  File "/usr/local/lib/python3.7/dist-packages/httpcore/_async/connection_pool.py", line 253, in handle_async_request
    raise exc
  File "/usr/local/lib/python3.7/dist-packages/httpcore/_async/connection_pool.py", line 237, in handle_async_request
    response = await connection.handle_async_request(request)
  File "/usr/local/lib/python3.7/dist-packages/httpcore/_async/connection.py", line 90, in handle_async_request
    return await self._connection.handle_async_request(request)
  File "/usr/local/lib/python3.7/dist-packages/httpcore/_async/http11.py", line 105, in handle_async_request
    raise exc
  File "/usr/local/lib/python3.7/dist-packages/httpcore/_async/http11.py", line 84, in handle_async_request
    ) = await self._receive_response_headers(**kwargs)
  File "/usr/local/lib/python3.7/dist-packages/httpcore/_async/http11.py", line 148, in _receive_response_headers
    event = await self._receive_event(timeout=timeout)
  File "/usr/local/lib/python3.7/dist-packages/httpcore/_async/http11.py", line 178, in _receive_event
    self.READ_NUM_BYTES, timeout=timeout
  File "/usr/local/lib/python3.7/dist-packages/httpcore/backends/asyncio.py", line 35, in read
    return b""
  File "/usr/lib/python3.7/contextlib.py", line 130, in __exit__
    self.gen.throw(type, value, traceback)
  File "/usr/local/lib/python3.7/dist-packages/httpcore/_exceptions.py", line 12, in map_exceptions
    raise to_exc(exc)
httpcore.ReadError

The above exception was the direct cause of the following exception:

Traceback (most recent call last):
  File "/usr/local/lib/python3.7/dist-packages/telegram/request/_httpxrequest.py", line 180, in do_request
    data=data,
  File "/usr/local/lib/python3.7/dist-packages/httpx/_client.py", line 1527, in request
    return await self.send(request, auth=auth, follow_redirects=follow_redirects)
  File "/usr/local/lib/python3.7/dist-packages/httpx/_client.py", line 1618, in send
    history=[],
  File "/usr/local/lib/python3.7/dist-packages/httpx/_client.py", line 1645, in _send_handling_auth
    history=history,
  File "/usr/local/lib/python3.7/dist-packages/httpx/_client.py", line 1679, in _send_handling_redirects
    response = await self._send_single_request(request)
  File "/usr/local/lib/python3.7/dist-packages/httpx/_client.py", line 1716, in _send_single_request
    response = await transport.handle_async_request(request)
  File "/usr/local/lib/python3.7/dist-packages/httpx/_transports/default.py", line 353, in handle_async_request
    resp = await self._pool.handle_async_request(req)
  File "/usr/lib/python3.7/contextlib.py", line 130, in __exit__
    self.gen.throw(type, value, traceback)
  File "/usr/local/lib/python3.7/dist-packages/httpx/_transports/default.py", line 77, in map_httpcore_exceptions
    raise mapped_exc(message) from exc
httpx.ReadError

The above exception was the direct cause of the following exception:

Traceback (most recent call last):
  File "/usr/local/lib/python3.7/dist-packages/telegram/ext/_updater.py", line 573, in _network_loop_retry
    if not await action_cb():
  File "/usr/local/lib/python3.7/dist-packages/telegram/ext/_updater.py", line 318, in polling_action_cb
    raise exc
  File "/usr/local/lib/python3.7/dist-packages/telegram/ext/_updater.py", line 310, in polling_action_cb
    allowed_updates=allowed_updates,
  File "/usr/local/lib/python3.7/dist-packages/telegram/ext/_extbot.py", line 489, in get_updates
    api_kwargs=api_kwargs,
  File "/usr/local/lib/python3.7/dist-packages/telegram/_bot.py", line 242, in decorator
    result = await func(*args, **kwargs)
  File "/usr/local/lib/python3.7/dist-packages/telegram/_bot.py", line 3899, in get_updates
    api_kwargs=api_kwargs,
  File "/usr/local/lib/python3.7/dist-packages/telegram/_bot.py", line 309, in _post
    pool_timeout=pool_timeout,
  File "/usr/local/lib/python3.7/dist-packages/telegram/ext/_extbot.py", line 287, in _do_post
    read_timeout=read_timeout,
  File "/usr/local/lib/python3.7/dist-packages/telegram/_bot.py", line 340, in _do_post
    pool_timeout=pool_timeout,
  File "/usr/local/lib/python3.7/dist-packages/telegram/request/_baserequest.py", line 169, in post
    pool_timeout=pool_timeout,
  File "/usr/local/lib/python3.7/dist-packages/telegram/request/_baserequest.py", line 285, in _request_wrapper
    raise exc
  File "/usr/local/lib/python3.7/dist-packages/telegram/request/_baserequest.py", line 278, in _request_wrapper
    pool_timeout=pool_timeout,
  File "/usr/local/lib/python3.7/dist-packages/telegram/request/_httpxrequest.py", line 195, in do_request
    raise NetworkError(f"httpx HTTPError: {err}") from err
telegram.error.NetworkError: httpx HTTPError: 
2022-11-10 13:46:30,524 - root - INFO - 910241302-https://t66y.com/htm_data/2211/7/5375137.html
2022-11-10 13:46:52,885 - root - INFO - 910241302-https://cl.2718x.xyz/htm_mob/2211/16/5366694.html
2022-11-10 14:29:15,149 - telegram.ext._updater - ERROR - Error while getting Updates: httpx HTTPError: 
2022-11-10 14:29:15,155 - telegram.ext._application - ERROR - No error handlers are registered, logging exception.
Traceback (most recent call last):
  File "/usr/lib/python3.7/asyncio/selector_events.py", line 801, in _read_ready__data_received
    data = self._sock.recv(self.max_size)
ConnectionResetError: [Errno 104] Connection reset by peer

The above exception was the direct cause of the following exception:

Traceback (most recent call last):
  File "/usr/local/lib/python3.7/dist-packages/httpcore/_exceptions.py", line 8, in map_exceptions
    yield
  File "/usr/local/lib/python3.7/dist-packages/httpcore/backends/asyncio.py", line 33, in read
    return await self._stream.receive(max_bytes=max_bytes)
  File "/usr/local/lib/python3.7/dist-packages/anyio/streams/tls.py", line 195, in receive
    data = await self._call_sslobject_method(self._ssl_object.read, max_bytes)
  File "/usr/local/lib/python3.7/dist-packages/anyio/streams/tls.py", line 137, in _call_sslobject_method
    data = await self.transport_stream.receive()
  File "/usr/local/lib/python3.7/dist-packages/anyio/_backends/_asyncio.py", line 1274, in receive
    raise self._protocol.exception
anyio.BrokenResourceError

During handling of the above exception, another exception occurred:

Traceback (most recent call last):
  File "/usr/local/lib/python3.7/dist-packages/httpx/_transports/default.py", line 60, in map_httpcore_exceptions
    yield
  File "/usr/local/lib/python3.7/dist-packages/httpx/_transports/default.py", line 353, in handle_async_request
    resp = await self._pool.handle_async_request(req)
  File "/usr/local/lib/python3.7/dist-packages/httpcore/_async/connection_pool.py", line 253, in handle_async_request
    raise exc
  File "/usr/local/lib/python3.7/dist-packages/httpcore/_async/connection_pool.py", line 237, in handle_async_request
    response = await connection.handle_async_request(request)
  File "/usr/local/lib/python3.7/dist-packages/httpcore/_async/connection.py", line 90, in handle_async_request
    return await self._connection.handle_async_request(request)
  File "/usr/local/lib/python3.7/dist-packages/httpcore/_async/http11.py", line 105, in handle_async_request
    raise exc
  File "/usr/local/lib/python3.7/dist-packages/httpcore/_async/http11.py", line 84, in handle_async_request
    ) = await self._receive_response_headers(**kwargs)
  File "/usr/local/lib/python3.7/dist-packages/httpcore/_async/http11.py", line 148, in _receive_response_headers
    event = await self._receive_event(timeout=timeout)
  File "/usr/local/lib/python3.7/dist-packages/httpcore/_async/http11.py", line 178, in _receive_event
    self.READ_NUM_BYTES, timeout=timeout
  File "/usr/local/lib/python3.7/dist-packages/httpcore/backends/asyncio.py", line 35, in read
    return b""
  File "/usr/lib/python3.7/contextlib.py", line 130, in __exit__
    self.gen.throw(type, value, traceback)
  File "/usr/local/lib/python3.7/dist-packages/httpcore/_exceptions.py", line 12, in map_exceptions
    raise to_exc(exc)
httpcore.ReadError

The above exception was the direct cause of the following exception:

Traceback (most recent call last):
  File "/usr/local/lib/python3.7/dist-packages/telegram/request/_httpxrequest.py", line 180, in do_request
    data=data,
  File "/usr/local/lib/python3.7/dist-packages/httpx/_client.py", line 1527, in request
    return await self.send(request, auth=auth, follow_redirects=follow_redirects)
  File "/usr/local/lib/python3.7/dist-packages/httpx/_client.py", line 1618, in send
    history=[],
  File "/usr/local/lib/python3.7/dist-packages/httpx/_client.py", line 1645, in _send_handling_auth
    history=history,
  File "/usr/local/lib/python3.7/dist-packages/httpx/_client.py", line 1679, in _send_handling_redirects
    response = await self._send_single_request(request)
  File "/usr/local/lib/python3.7/dist-packages/httpx/_client.py", line 1716, in _send_single_request
    response = await transport.handle_async_request(request)
  File "/usr/local/lib/python3.7/dist-packages/httpx/_transports/default.py", line 353, in handle_async_request
    resp = await self._pool.handle_async_request(req)
  File "/usr/lib/python3.7/contextlib.py", line 130, in __exit__
    self.gen.throw(type, value, traceback)
  File "/usr/local/lib/python3.7/dist-packages/httpx/_transports/default.py", line 77, in map_httpcore_exceptions
    raise mapped_exc(message) from exc
httpx.ReadError

The above exception was the direct cause of the following exception:

Traceback (most recent call last):
  File "/usr/local/lib/python3.7/dist-packages/telegram/ext/_updater.py", line 573, in _network_loop_retry
    if not await action_cb():
  File "/usr/local/lib/python3.7/dist-packages/telegram/ext/_updater.py", line 318, in polling_action_cb
    raise exc
  File "/usr/local/lib/python3.7/dist-packages/telegram/ext/_updater.py", line 310, in polling_action_cb
    allowed_updates=allowed_updates,
  File "/usr/local/lib/python3.7/dist-packages/telegram/ext/_extbot.py", line 489, in get_updates
    api_kwargs=api_kwargs,
  File "/usr/local/lib/python3.7/dist-packages/telegram/_bot.py", line 242, in decorator
    result = await func(*args, **kwargs)
  File "/usr/local/lib/python3.7/dist-packages/telegram/_bot.py", line 3899, in get_updates
    api_kwargs=api_kwargs,
  File "/usr/local/lib/python3.7/dist-packages/telegram/_bot.py", line 309, in _post
    pool_timeout=pool_timeout,
  File "/usr/local/lib/python3.7/dist-packages/telegram/ext/_extbot.py", line 287, in _do_post
    read_timeout=read_timeout,
  File "/usr/local/lib/python3.7/dist-packages/telegram/_bot.py", line 340, in _do_post
    pool_timeout=pool_timeout,
  File "/usr/local/lib/python3.7/dist-packages/telegram/request/_baserequest.py", line 169, in post
    pool_timeout=pool_timeout,
  File "/usr/local/lib/python3.7/dist-packages/telegram/request/_baserequest.py", line 285, in _request_wrapper
    raise exc
  File "/usr/local/lib/python3.7/dist-packages/telegram/request/_baserequest.py", line 278, in _request_wrapper
    pool_timeout=pool_timeout,
  File "/usr/local/lib/python3.7/dist-packages/telegram/request/_httpxrequest.py", line 195, in do_request
    raise NetworkError(f"httpx HTTPError: {err}") from err
telegram.error.NetworkError: httpx HTTPError: 
2022-11-10 15:26:43,108 - telegram.ext._application - ERROR - No error handlers are registered, logging exception.
Traceback (most recent call last):
  File "/usr/local/lib/python3.7/dist-packages/telegram/ext/_application.py", line 1002, in process_update
    await coroutine
  File "/usr/local/lib/python3.7/dist-packages/telegram/ext/_handler.py", line 137, in handle_update
    return await self.callback(update, context)
  File "/root/tg_bot/pxx.py", line 76, in show_at_random
    await context.bot.send_media_group(chat_id=update.effective_chat.id, media=pic_list)
  File "/usr/local/lib/python3.7/dist-packages/telegram/ext/_extbot.py", line 2240, in send_media_group
    api_kwargs=self._merge_api_rl_kwargs(api_kwargs, rate_limit_args),
  File "/usr/local/lib/python3.7/dist-packages/telegram/_bot.py", line 242, in decorator
    result = await func(*args, **kwargs)
  File "/usr/local/lib/python3.7/dist-packages/telegram/_bot.py", line 1994, in send_media_group
    api_kwargs=api_kwargs,
  File "/usr/local/lib/python3.7/dist-packages/telegram/_bot.py", line 309, in _post
    pool_timeout=pool_timeout,
  File "/usr/local/lib/python3.7/dist-packages/telegram/ext/_extbot.py", line 287, in _do_post
    read_timeout=read_timeout,
  File "/usr/local/lib/python3.7/dist-packages/telegram/_bot.py", line 340, in _do_post
    pool_timeout=pool_timeout,
  File "/usr/local/lib/python3.7/dist-packages/telegram/request/_baserequest.py", line 169, in post
    pool_timeout=pool_timeout,
  File "/usr/local/lib/python3.7/dist-packages/telegram/request/_baserequest.py", line 325, in _request_wrapper
    raise BadRequest(message)
telegram.error.BadRequest: Failed to send message #3 with the error message "photo_invalid_dimensions"
2022-11-10 15:27:35,003 - root - INFO - 910241302-https://t66y.com/htm_data/2211/8/5376339.html
2022-11-10 15:28:58,848 - root - INFO - 910241302-https://t66y.com/htm_data/2211/8/5376458.html
2022-11-10 15:29:24,822 - root - INFO - 910241302-https://t66y.com/htm_data/2211/8/5376596.html
2022-11-10 15:30:18,996 - root - INFO - 910241302-https://t66y.com/htm_data/2211/8/5376042.html
2022-11-10 15:30:33,190 - root - INFO - 910241302-https://t66y.com/htm_data/2211/8/5375435.html
2022-11-10 15:30:51,098 - root - INFO - 910241302-https://t66y.com/htm_data/2211/8/5375422.html
2022-11-10 15:31:18,874 - root - INFO - 910241302-https://t66y.com/htm_data/2211/8/5375346.html
2022-11-10 15:31:35,792 - root - INFO - 910241302-https://t66y.com/htm_data/2211/8/5375226.html
2022-11-10 15:32:17,369 - root - INFO - 910241302-https://t66y.com/htm_data/2211/8/5374916.html
2022-11-10 15:32:45,756 - root - INFO - 910241302-https://t66y.com/htm_data/2211/8/5374018.html
2022-11-10 15:33:17,467 - root - INFO - 910241302-https://t66y.com/htm_data/2211/8/5374067.html
2022-11-10 15:33:37,062 - root - INFO - 910241302-https://t66y.com/htm_data/2211/8/5374019.html
2022-11-10 15:33:50,763 - root - INFO - 910241302-https://t66y.com/htm_data/2211/8/5374021.html
2022-11-10 15:51:10,044 - root - INFO - 910241302-https://t66y.com/htm_mob/2209/7/5276030.html
2022-11-10 15:54:31,293 - root - INFO - 910241302-https://t66y.com/htm_mob/2211/8/5375346.html
2022-11-10 15:55:41,788 - root - INFO - 910241302-https://t66y.com/htm_mob/2211/8/5373280.html
2022-11-10 15:56:41,257 - root - INFO - 910241302-https://t66y.com/htm_mob/2211/8/5374021.html
2022-11-10 16:03:10,986 - root - INFO - 910241302-https://t66y.com/htm_mob/2211/7/5375483.html
2022-11-10 16:10:15,221 - root - INFO - 910241302-https://t66y.com/htm_mob/2209/7/5286116.html
2022-11-10 16:12:27,321 - root - INFO - 910241302-https://t66y.com/htm_mob/2211/7/5375425.html
2022-11-10 16:13:23,411 - root - INFO - 910241302-https://t66y.com/htm_mob/2211/7/5375456.html
2022-11-10 16:23:19,537 - telegram.ext._application - ERROR - No error handlers are registered, logging exception.
Traceback (most recent call last):
  File "/usr/local/lib/python3.7/dist-packages/httpcore/backends/asyncio.py", line 33, in read
    return await self._stream.receive(max_bytes=max_bytes)
  File "/usr/local/lib/python3.7/dist-packages/anyio/streams/tls.py", line 195, in receive
    data = await self._call_sslobject_method(self._ssl_object.read, max_bytes)
  File "/usr/local/lib/python3.7/dist-packages/anyio/streams/tls.py", line 137, in _call_sslobject_method
    data = await self.transport_stream.receive()
  File "/usr/local/lib/python3.7/dist-packages/anyio/_backends/_asyncio.py", line 1265, in receive
    await self._protocol.read_event.wait()
  File "/usr/lib/python3.7/asyncio/locks.py", line 293, in wait
    await fut
concurrent.futures._base.CancelledError

During handling of the above exception, another exception occurred:

Traceback (most recent call last):
  File "/usr/local/lib/python3.7/dist-packages/httpcore/_exceptions.py", line 8, in map_exceptions
    yield
  File "/usr/local/lib/python3.7/dist-packages/httpcore/backends/asyncio.py", line 35, in read
    return b""
  File "/usr/local/lib/python3.7/dist-packages/anyio/_core/_tasks.py", line 118, in __exit__
    raise TimeoutError
TimeoutError

During handling of the above exception, another exception occurred:

Traceback (most recent call last):
  File "/usr/local/lib/python3.7/dist-packages/httpx/_transports/default.py", line 60, in map_httpcore_exceptions
    yield
  File "/usr/local/lib/python3.7/dist-packages/httpx/_transports/default.py", line 353, in handle_async_request
    resp = await self._pool.handle_async_request(req)
  File "/usr/local/lib/python3.7/dist-packages/httpcore/_async/connection_pool.py", line 253, in handle_async_request
    raise exc
  File "/usr/local/lib/python3.7/dist-packages/httpcore/_async/connection_pool.py", line 237, in handle_async_request
    response = await connection.handle_async_request(request)
  File "/usr/local/lib/python3.7/dist-packages/httpcore/_async/connection.py", line 90, in handle_async_request
    return await self._connection.handle_async_request(request)
  File "/usr/local/lib/python3.7/dist-packages/httpcore/_async/http11.py", line 105, in handle_async_request
    raise exc
  File "/usr/local/lib/python3.7/dist-packages/httpcore/_async/http11.py", line 84, in handle_async_request
    ) = await self._receive_response_headers(**kwargs)
  File "/usr/local/lib/python3.7/dist-packages/httpcore/_async/http11.py", line 148, in _receive_response_headers
    event = await self._receive_event(timeout=timeout)
  File "/usr/local/lib/python3.7/dist-packages/httpcore/_async/http11.py", line 178, in _receive_event
    self.READ_NUM_BYTES, timeout=timeout
  File "/usr/local/lib/python3.7/dist-packages/httpcore/backends/asyncio.py", line 35, in read
    return b""
  File "/usr/lib/python3.7/contextlib.py", line 130, in __exit__
    self.gen.throw(type, value, traceback)
  File "/usr/local/lib/python3.7/dist-packages/httpcore/_exceptions.py", line 12, in map_exceptions
    raise to_exc(exc)
httpcore.ReadTimeout

The above exception was the direct cause of the following exception:

Traceback (most recent call last):
  File "/usr/local/lib/python3.7/dist-packages/telegram/request/_httpxrequest.py", line 180, in do_request
    data=data,
  File "/usr/local/lib/python3.7/dist-packages/httpx/_client.py", line 1527, in request
    return await self.send(request, auth=auth, follow_redirects=follow_redirects)
  File "/usr/local/lib/python3.7/dist-packages/httpx/_client.py", line 1618, in send
    history=[],
  File "/usr/local/lib/python3.7/dist-packages/httpx/_client.py", line 1645, in _send_handling_auth
    history=history,
  File "/usr/local/lib/python3.7/dist-packages/httpx/_client.py", line 1679, in _send_handling_redirects
    response = await self._send_single_request(request)
  File "/usr/local/lib/python3.7/dist-packages/httpx/_client.py", line 1716, in _send_single_request
    response = await transport.handle_async_request(request)
  File "/usr/local/lib/python3.7/dist-packages/httpx/_transports/default.py", line 353, in handle_async_request
    resp = await self._pool.handle_async_request(req)
  File "/usr/lib/python3.7/contextlib.py", line 130, in __exit__
    self.gen.throw(type, value, traceback)
  File "/usr/local/lib/python3.7/dist-packages/httpx/_transports/default.py", line 77, in map_httpcore_exceptions
    raise mapped_exc(message) from exc
httpx.ReadTimeout

The above exception was the direct cause of the following exception:

Traceback (most recent call last):
  File "/usr/local/lib/python3.7/dist-packages/telegram/ext/_application.py", line 1002, in process_update
    await coroutine
  File "/usr/local/lib/python3.7/dist-packages/telegram/ext/_handler.py", line 137, in handle_update
    return await self.callback(update, context)
  File "/root/tg_bot/pxx.py", line 76, in show_at_random
    await context.bot.send_media_group(chat_id=update.effective_chat.id, media=pic_list)
  File "/usr/local/lib/python3.7/dist-packages/telegram/ext/_extbot.py", line 2240, in send_media_group
    api_kwargs=self._merge_api_rl_kwargs(api_kwargs, rate_limit_args),
  File "/usr/local/lib/python3.7/dist-packages/telegram/_bot.py", line 242, in decorator
    result = await func(*args, **kwargs)
  File "/usr/local/lib/python3.7/dist-packages/telegram/_bot.py", line 1994, in send_media_group
    api_kwargs=api_kwargs,
  File "/usr/local/lib/python3.7/dist-packages/telegram/_bot.py", line 309, in _post
    pool_timeout=pool_timeout,
  File "/usr/local/lib/python3.7/dist-packages/telegram/ext/_extbot.py", line 287, in _do_post
    read_timeout=read_timeout,
  File "/usr/local/lib/python3.7/dist-packages/telegram/_bot.py", line 340, in _do_post
    pool_timeout=pool_timeout,
  File "/usr/local/lib/python3.7/dist-packages/telegram/request/_baserequest.py", line 169, in post
    pool_timeout=pool_timeout,
  File "/usr/local/lib/python3.7/dist-packages/telegram/request/_baserequest.py", line 285, in _request_wrapper
    raise exc
  File "/usr/local/lib/python3.7/dist-packages/telegram/request/_baserequest.py", line 278, in _request_wrapper
    pool_timeout=pool_timeout,
  File "/usr/local/lib/python3.7/dist-packages/telegram/request/_httpxrequest.py", line 191, in do_request
    raise TimedOut from err
telegram.error.TimedOut: Timed out
2022-11-11 01:05:34,221 - root - INFO - 910241302-https://t66y.com/htm_mob/2211/7/5377087.html
2022-11-11 03:40:42,894 - root - INFO - 910241302-https://t66y.com/htm_mob/2211/7/5377315.html
2022-11-11 03:55:59,097 - root - INFO - 910241302-https://t66y.com/htm_mob/2211/7/5376967.html
2022-11-11 03:56:19,748 - root - INFO - 910241302-https://t66y.com/htm_mob/2211/7/5376966.html
2022-11-11 04:04:53,664 - root - INFO - 910241302-https://t66y.com/htm_mob/2211/7/5377175.html
2022-11-11 04:08:35,625 - root - INFO - 910241302-https://t66y.com/htm_mob/2211/7/5377171.html
2022-11-11 04:13:45,723 - root - INFO - 910241302-https://t66y.com/htm_mob/2211/8/5377300.html
2022-11-11 04:18:17,861 - root - INFO - 910241302-https://t66y.com/htm_mob/2211/8/5377077.html
2022-11-11 04:19:07,213 - root - INFO - 910241302-https://t66y.com/htm_mob/2211/8/5376756.html
2022-11-11 09:58:32,723 - root - INFO - 910241302-https://t66y.com/htm_mob/2211/7/5377556.html
2022-11-11 10:09:19,609 - root - INFO - 910241302-https://t66y.com/htm_mob/2211/8/5376767.html
2022-11-11 10:09:58,071 - root - INFO - 910241302-https://t66y.com/htm_mob/2211/8/5376577.html
2022-11-11 10:11:16,986 - root - INFO - 910241302-https://t66y.com/htm_mob/2211/8/5378019.html
2022-11-11 10:11:54,058 - root - INFO - 910241302-https://t66y.com/htm_mob/2211/8/5377964.html
2022-11-11 10:12:53,731 - root - INFO - 910241302-https://t66y.com/htm_mob/2210/8/5358902.html
2022-11-11 10:13:18,080 - root - INFO - 910241302-https://t66y.com/htm_mob/2210/8/5357125.html
2022-11-11 10:14:47,005 - root - INFO - 910241302-https://t66y.com/htm_mob/2211/8/5368073.html
2022-11-11 10:16:06,412 - root - INFO - 910241302-https://t66y.com/htm_mob/2211/8/5376952.html
2022-11-11 10:16:29,023 - root - INFO - 910241302-https://t66y.com/htm_mob/2211/8/5375686.html
2022-11-11 10:17:02,067 - root - INFO - 910241302-https://t66y.com/htm_mob/2211/8/5377665.html
2022-11-11 10:18:29,750 - root - INFO - 910241302-https://t66y.com/htm_mob/2211/16/5348330.html
2022-11-11 10:20:17,210 - root - INFO - 910241302-https://t66y.com/htm_mob/2211/7/5377973.html
2022-11-11 10:23:22,490 - root - INFO - 910241302-https://t66y.com/htm_mob/2208/7/5217906.html
2022-11-11 10:24:00,164 - root - INFO - 910241302-https://t66y.com/htm_mob/2209/7/5294322.html
2022-11-11 10:24:08,833 - root - INFO - 910241302-https://t66y.com/htm_mob/2208/7/5232841.html
2022-11-11 10:24:26,273 - root - INFO - 910241302-https://t66y.com/htm_mob/2208/7/5209474.html
2022-11-11 10:24:47,144 - root - INFO - 910241302-https://t66y.com/htm_mob/2208/7/5237881.html
2022-11-11 10:26:15,414 - root - INFO - 910241302-https://t66y.com/htm_mob/2209/7/5294479.html
2022-11-11 10:27:48,360 - root - INFO - 910241302-https://t66y.com/htm_mob/2209/7/5301846.html
2022-11-11 10:30:09,716 - root - INFO - 910241302-https://t66y.com/htm_mob/2209/7/5285412.html
2022-11-11 10:30:46,887 - root - INFO - 910241302-https://t66y.com/htm_mob/2209/7/5273489.html
2022-11-11 10:31:13,752 - root - INFO - 910241302-https://t66y.com/htm_mob/2209/7/5259444.html
2022-11-11 10:31:56,166 - root - INFO - 910241302-https://t66y.com/htm_mob/2209/7/5261304.html
2022-11-11 11:53:54,803 - root - INFO - 910241302-https://t66y.com/htm_mob/2211/7/5378135.html
2022-11-11 11:58:25,851 - root - INFO - 910241302-https://t66y.com/htm_mob/2209/7/5297272.html
2022-11-11 11:58:51,517 - root - INFO - 910241302-https://t66y.com/htm_mob/2210/7/5305209.html
2022-11-11 11:59:20,336 - root - INFO - 910241302-https://t66y.com/htm_mob/2208/7/5247630.html
2022-11-11 11:59:42,704 - root - INFO - 910241302-https://t66y.com/htm_mob/2209/7/5274436.html
2022-11-11 12:00:30,841 - root - INFO - 910241302-https://t66y.com/htm_mob/2209/7/5300894.html
2022-11-11 12:00:56,403 - root - INFO - 910241302-https://t66y.com/htm_mob/2210/7/5305676.html
2022-11-11 12:01:26,782 - root - INFO - 910241302-https://t66y.com/htm_mob/2209/7/5285907.html
2022-11-11 12:02:13,201 - root - INFO - 910241302-https://t66y.com/htm_mob/2208/7/5249868.html
2022-11-11 12:02:41,302 - root - INFO - 910241302-https://t66y.com/htm_mob/2208/7/5248272.html
2022-11-11 12:03:08,581 - root - INFO - 910241302-https://t66y.com/htm_mob/2208/7/5223603.html
2022-11-11 12:04:12,221 - root - INFO - 910241302-https://t66y.com/htm_mob/2209/7/5295052.html
2022-11-11 12:04:32,187 - root - INFO - 910241302-https://t66y.com/htm_mob/2208/7/5228757.html
2022-11-11 12:05:07,360 - root - INFO - 910241302-https://t66y.com/htm_mob/2208/7/5229988.html
2022-11-11 12:05:28,151 - root - INFO - 910241302-https://t66y.com/htm_mob/2209/7/5294976.html
2022-11-11 12:06:35,489 - root - INFO - 910241302-https://t66y.com/htm_mob/2209/7/5301795.html
2022-11-11 12:07:14,650 - root - INFO - 910241302-https://t66y.com/htm_mob/2209/7/5267827.html
2022-11-11 12:07:53,178 - root - INFO - 910241302-https://t66y.com/htm_mob/2210/7/5309822.html
2022-11-11 12:08:36,643 - root - INFO - 910241302-https://t66y.com/htm_mob/2209/7/5281104.html
2022-11-11 12:09:34,224 - root - INFO - 910241302-https://t66y.com/htm_mob/2210/7/5340516.html
2022-11-11 12:10:06,928 - root - INFO - 910241302-https://t66y.com/htm_mob/2210/7/5346225.html
2022-11-11 12:11:34,830 - root - INFO - 910241302-https://t66y.com/htm_mob/2208/7/5256316.html
2022-11-11 12:12:55,769 - root - INFO - 910241302-https://t66y.com/htm_mob/2210/7/5334639.html
2022-11-11 12:13:46,993 - root - INFO - 910241302-https://t66y.com/htm_mob/2210/7/5306926.html
2022-11-11 12:14:16,411 - root - INFO - 910241302-https://t66y.com/htm_mob/2210/7/5311837.html
2022-11-11 12:19:37,698 - root - INFO - 910241302-https://t66y.com/htm_mob/2210/7/5347637.html
2022-11-11 12:20:20,467 - root - INFO - 910241302-https://t66y.com/htm_mob/2211/7/5366253.html
2022-11-11 12:21:20,481 - root - INFO - 910241302-https://t66y.com/htm_mob/2209/7/5282093.html
2022-11-11 12:21:54,934 - root - INFO - 910241302-https://t66y.com/htm_mob/2209/7/5277431.html
2022-11-11 12:28:52,327 - telegram.ext._application - ERROR - No error handlers are registered, logging exception.
Traceback (most recent call last):
  File "/usr/local/lib/python3.7/dist-packages/telegram/ext/_application.py", line 1002, in process_update
    await coroutine
  File "/usr/local/lib/python3.7/dist-packages/telegram/ext/_handler.py", line 137, in handle_update
    return await self.callback(update, context)
  File "/root/tg_bot/pxx.py", line 76, in show_at_random
    await context.bot.send_media_group(chat_id=update.effective_chat.id, media=pic_list)
  File "/usr/local/lib/python3.7/dist-packages/telegram/ext/_extbot.py", line 2240, in send_media_group
    api_kwargs=self._merge_api_rl_kwargs(api_kwargs, rate_limit_args),
  File "/usr/local/lib/python3.7/dist-packages/telegram/_bot.py", line 242, in decorator
    result = await func(*args, **kwargs)
  File "/usr/local/lib/python3.7/dist-packages/telegram/_bot.py", line 1994, in send_media_group
    api_kwargs=api_kwargs,
  File "/usr/local/lib/python3.7/dist-packages/telegram/_bot.py", line 309, in _post
    pool_timeout=pool_timeout,
  File "/usr/local/lib/python3.7/dist-packages/telegram/ext/_extbot.py", line 287, in _do_post
    read_timeout=read_timeout,
  File "/usr/local/lib/python3.7/dist-packages/telegram/_bot.py", line 340, in _do_post
    pool_timeout=pool_timeout,
  File "/usr/local/lib/python3.7/dist-packages/telegram/request/_baserequest.py", line 169, in post
    pool_timeout=pool_timeout,
  File "/usr/local/lib/python3.7/dist-packages/telegram/request/_baserequest.py", line 325, in _request_wrapper
    raise BadRequest(message)
telegram.error.BadRequest: File "/var/lib/engine/tmpfs_numa0/img_20221010_112442_683.png" of size 12237448 bytes is too big for a photo
2022-11-11 12:57:10,238 - telegram.ext._updater - ERROR - Error while getting Updates: httpx HTTPError: 
2022-11-11 12:57:10,242 - telegram.ext._application - ERROR - No error handlers are registered, logging exception.
Traceback (most recent call last):
  File "/usr/lib/python3.7/asyncio/selector_events.py", line 801, in _read_ready__data_received
    data = self._sock.recv(self.max_size)
ConnectionResetError: [Errno 104] Connection reset by peer

The above exception was the direct cause of the following exception:

Traceback (most recent call last):
  File "/usr/local/lib/python3.7/dist-packages/httpcore/_exceptions.py", line 8, in map_exceptions
    yield
  File "/usr/local/lib/python3.7/dist-packages/httpcore/backends/asyncio.py", line 33, in read
    return await self._stream.receive(max_bytes=max_bytes)
  File "/usr/local/lib/python3.7/dist-packages/anyio/streams/tls.py", line 195, in receive
    data = await self._call_sslobject_method(self._ssl_object.read, max_bytes)
  File "/usr/local/lib/python3.7/dist-packages/anyio/streams/tls.py", line 137, in _call_sslobject_method
    data = await self.transport_stream.receive()
  File "/usr/local/lib/python3.7/dist-packages/anyio/_backends/_asyncio.py", line 1274, in receive
    raise self._protocol.exception
anyio.BrokenResourceError

During handling of the above exception, another exception occurred:

Traceback (most recent call last):
  File "/usr/local/lib/python3.7/dist-packages/httpx/_transports/default.py", line 60, in map_httpcore_exceptions
    yield
  File "/usr/local/lib/python3.7/dist-packages/httpx/_transports/default.py", line 353, in handle_async_request
    resp = await self._pool.handle_async_request(req)
  File "/usr/local/lib/python3.7/dist-packages/httpcore/_async/connection_pool.py", line 253, in handle_async_request
    raise exc
  File "/usr/local/lib/python3.7/dist-packages/httpcore/_async/connection_pool.py", line 237, in handle_async_request
    response = await connection.handle_async_request(request)
  File "/usr/local/lib/python3.7/dist-packages/httpcore/_async/connection.py", line 90, in handle_async_request
    return await self._connection.handle_async_request(request)
  File "/usr/local/lib/python3.7/dist-packages/httpcore/_async/http11.py", line 105, in handle_async_request
    raise exc
  File "/usr/local/lib/python3.7/dist-packages/httpcore/_async/http11.py", line 84, in handle_async_request
    ) = await self._receive_response_headers(**kwargs)
  File "/usr/local/lib/python3.7/dist-packages/httpcore/_async/http11.py", line 148, in _receive_response_headers
    event = await self._receive_event(timeout=timeout)
  File "/usr/local/lib/python3.7/dist-packages/httpcore/_async/http11.py", line 178, in _receive_event
    self.READ_NUM_BYTES, timeout=timeout
  File "/usr/local/lib/python3.7/dist-packages/httpcore/backends/asyncio.py", line 35, in read
    return b""
  File "/usr/lib/python3.7/contextlib.py", line 130, in __exit__
    self.gen.throw(type, value, traceback)
  File "/usr/local/lib/python3.7/dist-packages/httpcore/_exceptions.py", line 12, in map_exceptions
    raise to_exc(exc)
httpcore.ReadError

The above exception was the direct cause of the following exception:

Traceback (most recent call last):
  File "/usr/local/lib/python3.7/dist-packages/telegram/request/_httpxrequest.py", line 180, in do_request
    data=data,
  File "/usr/local/lib/python3.7/dist-packages/httpx/_client.py", line 1527, in request
    return await self.send(request, auth=auth, follow_redirects=follow_redirects)
  File "/usr/local/lib/python3.7/dist-packages/httpx/_client.py", line 1618, in send
    history=[],
  File "/usr/local/lib/python3.7/dist-packages/httpx/_client.py", line 1645, in _send_handling_auth
    history=history,
  File "/usr/local/lib/python3.7/dist-packages/httpx/_client.py", line 1679, in _send_handling_redirects
    response = await self._send_single_request(request)
  File "/usr/local/lib/python3.7/dist-packages/httpx/_client.py", line 1716, in _send_single_request
    response = await transport.handle_async_request(request)
  File "/usr/local/lib/python3.7/dist-packages/httpx/_transports/default.py", line 353, in handle_async_request
    resp = await self._pool.handle_async_request(req)
  File "/usr/lib/python3.7/contextlib.py", line 130, in __exit__
    self.gen.throw(type, value, traceback)
  File "/usr/local/lib/python3.7/dist-packages/httpx/_transports/default.py", line 77, in map_httpcore_exceptions
    raise mapped_exc(message) from exc
httpx.ReadError

The above exception was the direct cause of the following exception:

Traceback (most recent call last):
  File "/usr/local/lib/python3.7/dist-packages/telegram/ext/_updater.py", line 573, in _network_loop_retry
    if not await action_cb():
  File "/usr/local/lib/python3.7/dist-packages/telegram/ext/_updater.py", line 318, in polling_action_cb
    raise exc
  File "/usr/local/lib/python3.7/dist-packages/telegram/ext/_updater.py", line 310, in polling_action_cb
    allowed_updates=allowed_updates,
  File "/usr/local/lib/python3.7/dist-packages/telegram/ext/_extbot.py", line 489, in get_updates
    api_kwargs=api_kwargs,
  File "/usr/local/lib/python3.7/dist-packages/telegram/_bot.py", line 242, in decorator
    result = await func(*args, **kwargs)
  File "/usr/local/lib/python3.7/dist-packages/telegram/_bot.py", line 3899, in get_updates
    api_kwargs=api_kwargs,
  File "/usr/local/lib/python3.7/dist-packages/telegram/_bot.py", line 309, in _post
    pool_timeout=pool_timeout,
  File "/usr/local/lib/python3.7/dist-packages/telegram/ext/_extbot.py", line 287, in _do_post
    read_timeout=read_timeout,
  File "/usr/local/lib/python3.7/dist-packages/telegram/_bot.py", line 340, in _do_post
    pool_timeout=pool_timeout,
  File "/usr/local/lib/python3.7/dist-packages/telegram/request/_baserequest.py", line 169, in post
    pool_timeout=pool_timeout,
  File "/usr/local/lib/python3.7/dist-packages/telegram/request/_baserequest.py", line 285, in _request_wrapper
    raise exc
  File "/usr/local/lib/python3.7/dist-packages/telegram/request/_baserequest.py", line 278, in _request_wrapper
    pool_timeout=pool_timeout,
  File "/usr/local/lib/python3.7/dist-packages/telegram/request/_httpxrequest.py", line 195, in do_request
    raise NetworkError(f"httpx HTTPError: {err}") from err
telegram.error.NetworkError: httpx HTTPError: 
2022-11-11 13:14:25,031 - telegram.ext._application - ERROR - No error handlers are registered, logging exception.
Traceback (most recent call last):
  File "/usr/local/lib/python3.7/dist-packages/telegram/ext/_application.py", line 1002, in process_update
    await coroutine
  File "/usr/local/lib/python3.7/dist-packages/telegram/ext/_handler.py", line 137, in handle_update
    return await self.callback(update, context)
  File "/root/tg_bot/pxx.py", line 76, in show_at_random
    await context.bot.send_media_group(chat_id=update.effective_chat.id, media=pic_list)
  File "/usr/local/lib/python3.7/dist-packages/telegram/ext/_extbot.py", line 2240, in send_media_group
    api_kwargs=self._merge_api_rl_kwargs(api_kwargs, rate_limit_args),
  File "/usr/local/lib/python3.7/dist-packages/telegram/_bot.py", line 242, in decorator
    result = await func(*args, **kwargs)
  File "/usr/local/lib/python3.7/dist-packages/telegram/_bot.py", line 1994, in send_media_group
    api_kwargs=api_kwargs,
  File "/usr/local/lib/python3.7/dist-packages/telegram/_bot.py", line 309, in _post
    pool_timeout=pool_timeout,
  File "/usr/local/lib/python3.7/dist-packages/telegram/ext/_extbot.py", line 287, in _do_post
    read_timeout=read_timeout,
  File "/usr/local/lib/python3.7/dist-packages/telegram/_bot.py", line 340, in _do_post
    pool_timeout=pool_timeout,
  File "/usr/local/lib/python3.7/dist-packages/telegram/request/_baserequest.py", line 169, in post
    pool_timeout=pool_timeout,
  File "/usr/local/lib/python3.7/dist-packages/telegram/request/_baserequest.py", line 325, in _request_wrapper
    raise BadRequest(message)
telegram.error.BadRequest: Failed to send message #8 with the error message "photo_invalid_dimensions"
2022-11-11 13:15:37,803 - telegram.ext._application - ERROR - No error handlers are registered, logging exception.
Traceback (most recent call last):
  File "/usr/local/lib/python3.7/dist-packages/telegram/ext/_application.py", line 1002, in process_update
    await coroutine
  File "/usr/local/lib/python3.7/dist-packages/telegram/ext/_handler.py", line 137, in handle_update
    return await self.callback(update, context)
  File "/root/tg_bot/pxx.py", line 76, in show_at_random
    await context.bot.send_media_group(chat_id=update.effective_chat.id, media=pic_list)
  File "/usr/local/lib/python3.7/dist-packages/telegram/ext/_extbot.py", line 2240, in send_media_group
    api_kwargs=self._merge_api_rl_kwargs(api_kwargs, rate_limit_args),
  File "/usr/local/lib/python3.7/dist-packages/telegram/_bot.py", line 242, in decorator
    result = await func(*args, **kwargs)
  File "/usr/local/lib/python3.7/dist-packages/telegram/_bot.py", line 1994, in send_media_group
    api_kwargs=api_kwargs,
  File "/usr/local/lib/python3.7/dist-packages/telegram/_bot.py", line 309, in _post
    pool_timeout=pool_timeout,
  File "/usr/local/lib/python3.7/dist-packages/telegram/ext/_extbot.py", line 287, in _do_post
    read_timeout=read_timeout,
  File "/usr/local/lib/python3.7/dist-packages/telegram/_bot.py", line 340, in _do_post
    pool_timeout=pool_timeout,
  File "/usr/local/lib/python3.7/dist-packages/telegram/request/_baserequest.py", line 169, in post
    pool_timeout=pool_timeout,
  File "/usr/local/lib/python3.7/dist-packages/telegram/request/_baserequest.py", line 325, in _request_wrapper
    raise BadRequest(message)
telegram.error.BadRequest: File "/var/lib/engine/tmpfs_numa0/4747246715863.jpg" of size 10525116 bytes is too big for a photo
2022-11-11 17:05:51,607 - root - INFO - 910241302-https://t66y.com/htm_mob/2211/7/5378445.html
2022-11-11 17:09:14,163 - root - INFO - 910241302-https://t66y.com/htm_mob/2209/7/5286482.html
2022-11-11 17:23:54,478 - root - INFO - 1905615710-https://t66y.com/htm_mob/2211/7/5375460.html
2022-11-11 22:13:04,500 - telegram.ext._updater - ERROR - Error while getting Updates: httpx HTTPError: 
2022-11-11 22:13:04,503 - telegram.ext._application - ERROR - No error handlers are registered, logging exception.
Traceback (most recent call last):
  File "/usr/lib/python3.7/asyncio/selector_events.py", line 801, in _read_ready__data_received
    data = self._sock.recv(self.max_size)
ConnectionResetError: [Errno 104] Connection reset by peer

The above exception was the direct cause of the following exception:

Traceback (most recent call last):
  File "/usr/local/lib/python3.7/dist-packages/httpcore/_exceptions.py", line 8, in map_exceptions
    yield
  File "/usr/local/lib/python3.7/dist-packages/httpcore/backends/asyncio.py", line 33, in read
    return await self._stream.receive(max_bytes=max_bytes)
  File "/usr/local/lib/python3.7/dist-packages/anyio/streams/tls.py", line 195, in receive
    data = await self._call_sslobject_method(self._ssl_object.read, max_bytes)
  File "/usr/local/lib/python3.7/dist-packages/anyio/streams/tls.py", line 137, in _call_sslobject_method
    data = await self.transport_stream.receive()
  File "/usr/local/lib/python3.7/dist-packages/anyio/_backends/_asyncio.py", line 1274, in receive
    raise self._protocol.exception
anyio.BrokenResourceError

During handling of the above exception, another exception occurred:

Traceback (most recent call last):
  File "/usr/local/lib/python3.7/dist-packages/httpx/_transports/default.py", line 60, in map_httpcore_exceptions
    yield
  File "/usr/local/lib/python3.7/dist-packages/httpx/_transports/default.py", line 353, in handle_async_request
    resp = await self._pool.handle_async_request(req)
  File "/usr/local/lib/python3.7/dist-packages/httpcore/_async/connection_pool.py", line 253, in handle_async_request
    raise exc
  File "/usr/local/lib/python3.7/dist-packages/httpcore/_async/connection_pool.py", line 237, in handle_async_request
    response = await connection.handle_async_request(request)
  File "/usr/local/lib/python3.7/dist-packages/httpcore/_async/connection.py", line 90, in handle_async_request
    return await self._connection.handle_async_request(request)
  File "/usr/local/lib/python3.7/dist-packages/httpcore/_async/http11.py", line 105, in handle_async_request
    raise exc
  File "/usr/local/lib/python3.7/dist-packages/httpcore/_async/http11.py", line 84, in handle_async_request
    ) = await self._receive_response_headers(**kwargs)
  File "/usr/local/lib/python3.7/dist-packages/httpcore/_async/http11.py", line 148, in _receive_response_headers
    event = await self._receive_event(timeout=timeout)
  File "/usr/local/lib/python3.7/dist-packages/httpcore/_async/http11.py", line 178, in _receive_event
    self.READ_NUM_BYTES, timeout=timeout
  File "/usr/local/lib/python3.7/dist-packages/httpcore/backends/asyncio.py", line 35, in read
    return b""
  File "/usr/lib/python3.7/contextlib.py", line 130, in __exit__
    self.gen.throw(type, value, traceback)
  File "/usr/local/lib/python3.7/dist-packages/httpcore/_exceptions.py", line 12, in map_exceptions
    raise to_exc(exc)
httpcore.ReadError

The above exception was the direct cause of the following exception:

Traceback (most recent call last):
  File "/usr/local/lib/python3.7/dist-packages/telegram/request/_httpxrequest.py", line 180, in do_request
    data=data,
  File "/usr/local/lib/python3.7/dist-packages/httpx/_client.py", line 1527, in request
    return await self.send(request, auth=auth, follow_redirects=follow_redirects)
  File "/usr/local/lib/python3.7/dist-packages/httpx/_client.py", line 1618, in send
    history=[],
  File "/usr/local/lib/python3.7/dist-packages/httpx/_client.py", line 1645, in _send_handling_auth
    history=history,
  File "/usr/local/lib/python3.7/dist-packages/httpx/_client.py", line 1679, in _send_handling_redirects
    response = await self._send_single_request(request)
  File "/usr/local/lib/python3.7/dist-packages/httpx/_client.py", line 1716, in _send_single_request
    response = await transport.handle_async_request(request)
  File "/usr/local/lib/python3.7/dist-packages/httpx/_transports/default.py", line 353, in handle_async_request
    resp = await self._pool.handle_async_request(req)
  File "/usr/lib/python3.7/contextlib.py", line 130, in __exit__
    self.gen.throw(type, value, traceback)
  File "/usr/local/lib/python3.7/dist-packages/httpx/_transports/default.py", line 77, in map_httpcore_exceptions
    raise mapped_exc(message) from exc
httpx.ReadError

The above exception was the direct cause of the following exception:

Traceback (most recent call last):
  File "/usr/local/lib/python3.7/dist-packages/telegram/ext/_updater.py", line 573, in _network_loop_retry
    if not await action_cb():
  File "/usr/local/lib/python3.7/dist-packages/telegram/ext/_updater.py", line 318, in polling_action_cb
    raise exc
  File "/usr/local/lib/python3.7/dist-packages/telegram/ext/_updater.py", line 310, in polling_action_cb
    allowed_updates=allowed_updates,
  File "/usr/local/lib/python3.7/dist-packages/telegram/ext/_extbot.py", line 489, in get_updates
    api_kwargs=api_kwargs,
  File "/usr/local/lib/python3.7/dist-packages/telegram/_bot.py", line 242, in decorator
    result = await func(*args, **kwargs)
  File "/usr/local/lib/python3.7/dist-packages/telegram/_bot.py", line 3899, in get_updates
    api_kwargs=api_kwargs,
  File "/usr/local/lib/python3.7/dist-packages/telegram/_bot.py", line 309, in _post
    pool_timeout=pool_timeout,
  File "/usr/local/lib/python3.7/dist-packages/telegram/ext/_extbot.py", line 287, in _do_post
    read_timeout=read_timeout,
  File "/usr/local/lib/python3.7/dist-packages/telegram/_bot.py", line 340, in _do_post
    pool_timeout=pool_timeout,
  File "/usr/local/lib/python3.7/dist-packages/telegram/request/_baserequest.py", line 169, in post
    pool_timeout=pool_timeout,
  File "/usr/local/lib/python3.7/dist-packages/telegram/request/_baserequest.py", line 285, in _request_wrapper
    raise exc
  File "/usr/local/lib/python3.7/dist-packages/telegram/request/_baserequest.py", line 278, in _request_wrapper
    pool_timeout=pool_timeout,
  File "/usr/local/lib/python3.7/dist-packages/telegram/request/_httpxrequest.py", line 195, in do_request
    raise NetworkError(f"httpx HTTPError: {err}") from err
telegram.error.NetworkError: httpx HTTPError: 
2022-11-11 22:43:06,359 - telegram.ext._updater - ERROR - Error while getting Updates: httpx HTTPError: 
2022-11-11 22:43:06,361 - telegram.ext._application - ERROR - No error handlers are registered, logging exception.
Traceback (most recent call last):
  File "/usr/lib/python3.7/asyncio/selector_events.py", line 801, in _read_ready__data_received
    data = self._sock.recv(self.max_size)
ConnectionResetError: [Errno 104] Connection reset by peer

The above exception was the direct cause of the following exception:

Traceback (most recent call last):
  File "/usr/local/lib/python3.7/dist-packages/httpcore/_exceptions.py", line 8, in map_exceptions
    yield
  File "/usr/local/lib/python3.7/dist-packages/httpcore/backends/asyncio.py", line 33, in read
    return await self._stream.receive(max_bytes=max_bytes)
  File "/usr/local/lib/python3.7/dist-packages/anyio/streams/tls.py", line 195, in receive
    data = await self._call_sslobject_method(self._ssl_object.read, max_bytes)
  File "/usr/local/lib/python3.7/dist-packages/anyio/streams/tls.py", line 137, in _call_sslobject_method
    data = await self.transport_stream.receive()
  File "/usr/local/lib/python3.7/dist-packages/anyio/_backends/_asyncio.py", line 1274, in receive
    raise self._protocol.exception
anyio.BrokenResourceError

During handling of the above exception, another exception occurred:

Traceback (most recent call last):
  File "/usr/local/lib/python3.7/dist-packages/httpx/_transports/default.py", line 60, in map_httpcore_exceptions
    yield
  File "/usr/local/lib/python3.7/dist-packages/httpx/_transports/default.py", line 353, in handle_async_request
    resp = await self._pool.handle_async_request(req)
  File "/usr/local/lib/python3.7/dist-packages/httpcore/_async/connection_pool.py", line 253, in handle_async_request
    raise exc
  File "/usr/local/lib/python3.7/dist-packages/httpcore/_async/connection_pool.py", line 237, in handle_async_request
    response = await connection.handle_async_request(request)
  File "/usr/local/lib/python3.7/dist-packages/httpcore/_async/connection.py", line 90, in handle_async_request
    return await self._connection.handle_async_request(request)
  File "/usr/local/lib/python3.7/dist-packages/httpcore/_async/http11.py", line 105, in handle_async_request
    raise exc
  File "/usr/local/lib/python3.7/dist-packages/httpcore/_async/http11.py", line 84, in handle_async_request
    ) = await self._receive_response_headers(**kwargs)
  File "/usr/local/lib/python3.7/dist-packages/httpcore/_async/http11.py", line 148, in _receive_response_headers
    event = await self._receive_event(timeout=timeout)
  File "/usr/local/lib/python3.7/dist-packages/httpcore/_async/http11.py", line 178, in _receive_event
    self.READ_NUM_BYTES, timeout=timeout
  File "/usr/local/lib/python3.7/dist-packages/httpcore/backends/asyncio.py", line 35, in read
    return b""
  File "/usr/lib/python3.7/contextlib.py", line 130, in __exit__
    self.gen.throw(type, value, traceback)
  File "/usr/local/lib/python3.7/dist-packages/httpcore/_exceptions.py", line 12, in map_exceptions
    raise to_exc(exc)
httpcore.ReadError

The above exception was the direct cause of the following exception:

Traceback (most recent call last):
  File "/usr/local/lib/python3.7/dist-packages/telegram/request/_httpxrequest.py", line 180, in do_request
    data=data,
  File "/usr/local/lib/python3.7/dist-packages/httpx/_client.py", line 1527, in request
    return await self.send(request, auth=auth, follow_redirects=follow_redirects)
  File "/usr/local/lib/python3.7/dist-packages/httpx/_client.py", line 1618, in send
    history=[],
  File "/usr/local/lib/python3.7/dist-packages/httpx/_client.py", line 1645, in _send_handling_auth
    history=history,
  File "/usr/local/lib/python3.7/dist-packages/httpx/_client.py", line 1679, in _send_handling_redirects
    response = await self._send_single_request(request)
  File "/usr/local/lib/python3.7/dist-packages/httpx/_client.py", line 1716, in _send_single_request
    response = await transport.handle_async_request(request)
  File "/usr/local/lib/python3.7/dist-packages/httpx/_transports/default.py", line 353, in handle_async_request
    resp = await self._pool.handle_async_request(req)
  File "/usr/lib/python3.7/contextlib.py", line 130, in __exit__
    self.gen.throw(type, value, traceback)
  File "/usr/local/lib/python3.7/dist-packages/httpx/_transports/default.py", line 77, in map_httpcore_exceptions
    raise mapped_exc(message) from exc
httpx.ReadError

The above exception was the direct cause of the following exception:

Traceback (most recent call last):
  File "/usr/local/lib/python3.7/dist-packages/telegram/ext/_updater.py", line 573, in _network_loop_retry
    if not await action_cb():
  File "/usr/local/lib/python3.7/dist-packages/telegram/ext/_updater.py", line 318, in polling_action_cb
    raise exc
  File "/usr/local/lib/python3.7/dist-packages/telegram/ext/_updater.py", line 310, in polling_action_cb
    allowed_updates=allowed_updates,
  File "/usr/local/lib/python3.7/dist-packages/telegram/ext/_extbot.py", line 489, in get_updates
    api_kwargs=api_kwargs,
  File "/usr/local/lib/python3.7/dist-packages/telegram/_bot.py", line 242, in decorator
    result = await func(*args, **kwargs)
  File "/usr/local/lib/python3.7/dist-packages/telegram/_bot.py", line 3899, in get_updates
    api_kwargs=api_kwargs,
  File "/usr/local/lib/python3.7/dist-packages/telegram/_bot.py", line 309, in _post
    pool_timeout=pool_timeout,
  File "/usr/local/lib/python3.7/dist-packages/telegram/ext/_extbot.py", line 287, in _do_post
    read_timeout=read_timeout,
  File "/usr/local/lib/python3.7/dist-packages/telegram/_bot.py", line 340, in _do_post
    pool_timeout=pool_timeout,
  File "/usr/local/lib/python3.7/dist-packages/telegram/request/_baserequest.py", line 169, in post
    pool_timeout=pool_timeout,
  File "/usr/local/lib/python3.7/dist-packages/telegram/request/_baserequest.py", line 285, in _request_wrapper
    raise exc
  File "/usr/local/lib/python3.7/dist-packages/telegram/request/_baserequest.py", line 278, in _request_wrapper
    pool_timeout=pool_timeout,
  File "/usr/local/lib/python3.7/dist-packages/telegram/request/_httpxrequest.py", line 195, in do_request
    raise NetworkError(f"httpx HTTPError: {err}") from err
telegram.error.NetworkError: httpx HTTPError: 
2022-11-12 01:15:48,602 - root - INFO - 910241302-https://t66y.com/htm_mob/2211/7/5379235.html
2022-11-12 01:19:59,459 - root - INFO - 910241302-https://t66y.com/htm_mob/2211/7/5379220.html
2022-11-12 01:24:55,155 - root - INFO - 910241302-https://t66y.com/htm_mob/2211/7/5379234.html
2022-11-12 03:20:54,598 - root - INFO - 910241302-https://t66y.com/htm_mob/2211/7/5379356.html
2022-11-12 03:22:00,701 - root - INFO - 910241302-https://t66y.com/htm_mob/2211/7/5379010.html
2022-11-12 03:34:21,858 - root - INFO - 910241302-https://t66y.com/htm_mob/2209/7/5298104.html
2022-11-12 03:34:58,595 - root - INFO - 910241302-https://t66y.com/htm_mob/2211/7/5374690.html
2022-11-12 03:44:06,726 - root - INFO - 910241302-https://t66y.com/htm_mob/2211/7/5378542.html
2022-11-12 16:01:01,539 - root - INFO - 910241302-https://t66y.com/htm_data/2211/7/5379690.html
2022-11-12 16:01:10,337 - root - INFO - 910241302-https://t66y.com/htm_data/2211/7/5379763.html
2022-11-12 16:09:53,334 - root - INFO - 910241302-https://t66y.com/htm_data/2211/7/5376967.html
2022-11-12 16:17:06,411 - root - INFO - 910241302-https://t66y.com/htm_mob/2211/7/5372574.html
2022-11-12 16:18:40,273 - root - INFO - 910241302-https://t66y.com/htm_mob/2211/7/5379042.html
2022-11-12 16:19:32,287 - root - INFO - 910241302-https://t66y.com/htm_mob/2211/7/5366472.html
2022-11-12 16:20:12,103 - root - INFO - 910241302-https://t66y.com/htm_mob/2211/7/5379517.html
2022-11-12 16:21:10,094 - root - INFO - 910241302-https://t66y.com/htm_mob/2210/7/5313856.html
2022-11-13 08:05:04,043 - root - INFO - 1905615710-aa
2022-11-13 08:06:02,572 - telegram.ext._application - ERROR - No error handlers are registered, logging exception.
Traceback (most recent call last):
  File "/usr/local/lib/python3.7/dist-packages/httpcore/backends/asyncio.py", line 112, in connect_tcp
    local_host=local_address,
  File "/usr/local/lib/python3.7/dist-packages/anyio/_core/_sockets.py", line 218, in connect_tcp
    await event.wait()
  File "/usr/local/lib/python3.7/dist-packages/anyio/_backends/_asyncio.py", line 658, in __aexit__
    raise CancelledError
concurrent.futures._base.CancelledError

During handling of the above exception, another exception occurred:

Traceback (most recent call last):
  File "/usr/local/lib/python3.7/dist-packages/httpcore/_exceptions.py", line 8, in map_exceptions
    yield
  File "/usr/local/lib/python3.7/dist-packages/httpcore/backends/asyncio.py", line 112, in connect_tcp
    local_host=local_address,
  File "/usr/local/lib/python3.7/dist-packages/anyio/_core/_tasks.py", line 118, in __exit__
    raise TimeoutError
TimeoutError

During handling of the above exception, another exception occurred:

Traceback (most recent call last):
  File "/usr/local/lib/python3.7/dist-packages/httpx/_transports/default.py", line 60, in map_httpcore_exceptions
    yield
  File "/usr/local/lib/python3.7/dist-packages/httpx/_transports/default.py", line 353, in handle_async_request
    resp = await self._pool.handle_async_request(req)
  File "/usr/local/lib/python3.7/dist-packages/httpcore/_async/connection_pool.py", line 253, in handle_async_request
    raise exc
  File "/usr/local/lib/python3.7/dist-packages/httpcore/_async/connection_pool.py", line 237, in handle_async_request
    response = await connection.handle_async_request(request)
  File "/usr/local/lib/python3.7/dist-packages/httpcore/_async/connection.py", line 86, in handle_async_request
    raise exc
  File "/usr/local/lib/python3.7/dist-packages/httpcore/_async/connection.py", line 63, in handle_async_request
    stream = await self._connect(request)
  File "/usr/local/lib/python3.7/dist-packages/httpcore/_async/connection.py", line 111, in _connect
    stream = await self._network_backend.connect_tcp(**kwargs)
  File "/usr/local/lib/python3.7/dist-packages/httpcore/backends/auto.py", line 30, in connect_tcp
    host, port, timeout=timeout, local_address=local_address
  File "/usr/local/lib/python3.7/dist-packages/httpcore/backends/asyncio.py", line 112, in connect_tcp
    local_host=local_address,
  File "/usr/lib/python3.7/contextlib.py", line 130, in __exit__
    self.gen.throw(type, value, traceback)
  File "/usr/local/lib/python3.7/dist-packages/httpcore/_exceptions.py", line 12, in map_exceptions
    raise to_exc(exc)
httpcore.ConnectTimeout

The above exception was the direct cause of the following exception:

Traceback (most recent call last):
  File "/usr/local/lib/python3.7/dist-packages/telegram/request/_httpxrequest.py", line 180, in do_request
    data=data,
  File "/usr/local/lib/python3.7/dist-packages/httpx/_client.py", line 1527, in request
    return await self.send(request, auth=auth, follow_redirects=follow_redirects)
  File "/usr/local/lib/python3.7/dist-packages/httpx/_client.py", line 1618, in send
    history=[],
  File "/usr/local/lib/python3.7/dist-packages/httpx/_client.py", line 1645, in _send_handling_auth
    history=history,
  File "/usr/local/lib/python3.7/dist-packages/httpx/_client.py", line 1679, in _send_handling_redirects
    response = await self._send_single_request(request)
  File "/usr/local/lib/python3.7/dist-packages/httpx/_client.py", line 1716, in _send_single_request
    response = await transport.handle_async_request(request)
  File "/usr/local/lib/python3.7/dist-packages/httpx/_transports/default.py", line 353, in handle_async_request
    resp = await self._pool.handle_async_request(req)
  File "/usr/lib/python3.7/contextlib.py", line 130, in __exit__
    self.gen.throw(type, value, traceback)
  File "/usr/local/lib/python3.7/dist-packages/httpx/_transports/default.py", line 77, in map_httpcore_exceptions
    raise mapped_exc(message) from exc
httpx.ConnectTimeout

The above exception was the direct cause of the following exception:

Traceback (most recent call last):
  File "/usr/local/lib/python3.7/dist-packages/telegram/ext/_application.py", line 1002, in process_update
    await coroutine
  File "/usr/local/lib/python3.7/dist-packages/telegram/ext/_handler.py", line 137, in handle_update
    return await self.callback(update, context)
  File "/root/tg_bot/pxx.py", line 63, in echo
    await context.bot.send_message(chat_id=update.effective_chat.id, text=str(get_url.get_1024_url(str(url))))
  File "/usr/local/lib/python3.7/dist-packages/telegram/ext/_extbot.py", line 2278, in send_message
    api_kwargs=self._merge_api_rl_kwargs(api_kwargs, rate_limit_args),
  File "/usr/local/lib/python3.7/dist-packages/telegram/_bot.py", line 242, in decorator
    result = await func(*args, **kwargs)
  File "/usr/local/lib/python3.7/dist-packages/telegram/_bot.py", line 674, in send_message
    api_kwargs=api_kwargs,
  File "/usr/local/lib/python3.7/dist-packages/telegram/ext/_extbot.py", line 461, in _send_message
    api_kwargs=api_kwargs,
  File "/usr/local/lib/python3.7/dist-packages/telegram/_bot.py", line 378, in _send_message
    api_kwargs=api_kwargs,
  File "/usr/local/lib/python3.7/dist-packages/telegram/_bot.py", line 309, in _post
    pool_timeout=pool_timeout,
  File "/usr/local/lib/python3.7/dist-packages/telegram/ext/_extbot.py", line 287, in _do_post
    read_timeout=read_timeout,
  File "/usr/local/lib/python3.7/dist-packages/telegram/_bot.py", line 340, in _do_post
    pool_timeout=pool_timeout,
  File "/usr/local/lib/python3.7/dist-packages/telegram/request/_baserequest.py", line 169, in post
    pool_timeout=pool_timeout,
  File "/usr/local/lib/python3.7/dist-packages/telegram/request/_baserequest.py", line 285, in _request_wrapper
    raise exc
  File "/usr/local/lib/python3.7/dist-packages/telegram/request/_baserequest.py", line 278, in _request_wrapper
    pool_timeout=pool_timeout,
  File "/usr/local/lib/python3.7/dist-packages/telegram/request/_httpxrequest.py", line 191, in do_request
    raise TimedOut from err
telegram.error.TimedOut: Timed out
2022-11-13 08:06:26,611 - root - INFO - 1905615710-aaaa
2022-11-13 08:06:37,389 - root - INFO - 1905615710-aaa
2022-11-13 10:47:08,188 - telegram.ext._application - ERROR - No error handlers are registered, logging exception.
Traceback (most recent call last):
  File "/usr/local/lib/python3.7/dist-packages/telegram/ext/_application.py", line 1002, in process_update
    await coroutine
  File "/usr/local/lib/python3.7/dist-packages/telegram/ext/_handler.py", line 137, in handle_update
    return await self.callback(update, context)
  File "/root/tg_bot/pxx.py", line 76, in show_at_random
    result = sample(img_list,9)
  File "/usr/local/lib/python3.7/dist-packages/telegram/ext/_extbot.py", line 2240, in send_media_group
    api_kwargs=self._merge_api_rl_kwargs(api_kwargs, rate_limit_args),
  File "/usr/local/lib/python3.7/dist-packages/telegram/_bot.py", line 242, in decorator
    result = await func(*args, **kwargs)
  File "/usr/local/lib/python3.7/dist-packages/telegram/_bot.py", line 1994, in send_media_group
    api_kwargs=api_kwargs,
  File "/usr/local/lib/python3.7/dist-packages/telegram/_bot.py", line 309, in _post
    pool_timeout=pool_timeout,
  File "/usr/local/lib/python3.7/dist-packages/telegram/ext/_extbot.py", line 287, in _do_post
    read_timeout=read_timeout,
  File "/usr/local/lib/python3.7/dist-packages/telegram/_bot.py", line 340, in _do_post
    pool_timeout=pool_timeout,
  File "/usr/local/lib/python3.7/dist-packages/telegram/request/_baserequest.py", line 169, in post
    pool_timeout=pool_timeout,
  File "/usr/local/lib/python3.7/dist-packages/telegram/request/_baserequest.py", line 325, in _request_wrapper
    raise BadRequest(message)
telegram.error.BadRequest: Failed to send message #1 with the error message "photo_invalid_dimensions"
